Workbook

Sheet Index
A1: SPECIFIC MODIFICATIONS OF LIQUID METALS:
A2: 1. | B2: Surface reneval | C2: Damköhler number | D2: Da_s
A3: 2.
A4: 3.
A5: 4.

Sheet Kinetic parameters
A1: ISOTHERMAL
A2: Inputs | B2: Const. | C2: Units | E2: Results
A3: Temp | B3: 1273 | C3: K
A4: Pressión | B4: 1.01325 | C4: Pa
A5: R | B5: 8.314 | C5: J/mol·K
A6: Reaction Rate Constants | E6: Arrheniu's law
A7: A_DRM | B7: ='Domain-Shift'!L6 -> 1290000 | C7: mol/m3·s | E7: k_4 = k_DRM | F7: =B7*EXP(-B8/(B5*B3)) -> 0.01063785
A8: Ea_DRM | B8: ='Domain-Shift'!L7 -> 197000 | C8: J/mol | E8: k_11 = k_RWGS | F8: =B9*EXP(-B10/(B5*B3)) -> 35.2645
A9: A_RWGS | B9: ='Domain-Shift'!L8 -> 350000 | C9: mol/m3·s | E9: k_crack | F9: =B11*EXP(-B12/(B5*B3)) -> 1.1347074e-11
A10: Ea_RWGS | B10: ='Domain-Shift'!L9 -> 97400 | C10: J/mol | E10: k_boud | F10: =B13*EXP(-B14/(B5*B3)) -> 1.0572735e-12
A11: A_crack | B11: 0.08 | C11: mol/m3·s | E11: k_gas,H2O
A12: Ea_crack | B12: 240000 | C12: J/mol
A13: A_boud | B13: 1e-05 | C13: mol/m3·s
A14: Ea_boud | B14: 170000 | C14: J/mol
A15: Adsorption Constants | E15: Van't Hoff form
A16: K_1 = K_CH4 | B16: ='Domain-Shift'!L11 -> 0.026 | C16: 1/bar | E16: K_1 = K_CH4 | F16: =B16*EXP(-B17/(B5*B3)) -> 0.26099632 | G16: 1/bar | H16: =F16*0.00001 -> 2.6099632e-06 | I16: 1/Pa
A17: dH_1=dH_CH4 | B17: ='Domain-Shift'!L12 -> -24410.4 | C17: J/mol | E17: K_2 = K_CO2 | F17: =B18*EXP(-B19/(B5*B3)) -> 0.22048615 | G17: 1/bar | H17: =F17*0.00001 -> 2.2048615e-06 | I17: 1/Pa
A18: K_2 = K_CO2 | B18: ='Domain-Shift'!L13 -> 0.0261 | C18: 1/bar | E18: K_3 = K_H2 | F18: =B20*EXP(-B21/(B5*B3)) -> 0.00017022595 | G18: 1/bar | H18: =F18*0.00001 -> 1.7022595e-09 | I18: 1/Pa
A19: dH_2=dH_CO2 | B19: ='Domain-Shift'!L14 -> -22584.6 | C19: J/mol | E19: K_-21 = K_C0 | F19: =B22*EXP(-B23/(B5*B3)) -> 2.1742078e-05 | G19: 1/bar | H19: =F19*0.00001 -> 2.1742078e-10 | I19: 1/Pa
A20: K_3 = K_H2 | B20: ='Domain-Shift'!L15 -> 1e-05 | C20: 1/bar | E20: K_-23 = K_H2O | F20: =B24*EXP(-B25/(B5*B3)) -> 0.0012078386 | G20: 1/bar | H20: =F20*0.00001 -> 1.2078386e-08 | I20: 1/Pa
A21: dH_3=dH_H2 | B21: ='Domain-Shift'!L16 -> -30000 | C21: J/mol
A22: K_-21 = K_CO | B22: ='Domain-Shift'!L17 -> 1e-05 | C22: 1/bar
A23: dH_-21=dH_CO | B23: ='Domain-Shift'!L18 -> -8220 | C23: J/mol
A24: K_-23 = K_H2O | B24: ='Domain-Shift'!L19 -> 4.73e-06 | C24: 1/bar
A25: dH_-23=dH_H2O | B25: ='Domain-Shift'!L20 -> -58662 | C25: J/mol
A26: Equilibrium Constants | E26: Dimensionless
A27: K4 = K_DRM | B27: ='Domain-Shift'!L22 -> 678000000000000
A28: dH_4 = dH_DRM | B28: ='Domain-Shift'!L23 -> 259660 | E28: K_DRM | F28: =B27*EXP(-B28/(B5*B3)) -> 15006.913 | G28: K_eq_DRM | H28: =1/F28 -> 6.6635956e-05
A29: K_11 = K_RWGS | B29: ='Domain-Shift'!L24 -> 56.4971 | E29: K_RWGS | F29: =B29*EXP(-B30/(B5*B3)) -> 1.7823599 | G29: K_eq_RWGS | H29: =1/F29 -> 0.56105391
A30: dH_11 = dH_RWGS | B30: ='Domain-Shift'!L25 -> 36580

Sheet Domain-Shift
B1: R= | C1: 8.314 | D1: J/mol K
B2: T= | C2: 1023 | D2: K
A3: DRM & RWGS
A4: Benguerba et al. | J4: BEP Scaling | T4: Temperature | U4: 723 | V4: 773 | W4: 823 | X4: 873 | Y4: 923 | Z4: 973 | AA4: 1023 | AB4: 1073 | AC4: 1123 | AD4: 1173 | AE4: 1223 | AF4: 1273
B5: Reaction Rate Constants | F5: CONSTANTS | K5: Reaction Rate Constants | O5: CONSTANTS | T5: r_DRM | U5: 9.54431e-05 | V5: 0.000185213 | W5: 0.000327357 | X5: 0.000525895 | Y5: 0.000750325 | Z5: 0.00094706 | AA5: 0.0010828 | AB5: 0.00116278 | AC5: 0.00120601 | AD5: 0.00122984 | AE5: 0.00124193 | AF5: 0.00124922
B6: A_DRM | C6: 1290000 | D6: mol/kg·s | F6: k_DRM | G6: =C6*EXP(-C7/($C$1*$C$2)) -> 7.9238573 | K6: A_DRM | L6: 1290000 | M6: mol/kg·s | O6: k_DRM | P6: =L6*EXP(-L7/($C$1*$C$2)) -> 0.00011255281 | T6: r_RWGS | U6: 0.000153838 | V6: 0.000286939 | W6: 0.000466824 | X6: 0.000684363 | Y6: 0.000898109 | Z6: 0.00106203 | AA6: 0.00116222 | AB6: 0.00121525 | AC6: 0.00124143 | AD6: 0.00125638 | AE6: 0.00126506 | AF6: 0.00126962
B7: Ea_DRM | C7: 102065 | D7: J/mol | K7: Ea_DRM | L7: 197000 | M7: J/mol | S7: 110265
B8: A_RWGS | C8: 350000 | D8: mol/kg·s | F8: k_RWGS | G8: =C8*EXP(-C9/($C$1*$C$2)) -> 25.498006 | K8: A_RWGS | L8: 350000 | M8: mol/kg·s | O8: k_RWGS | P8: =L8*EXP(-L9/($C$1*$C$2)) -> 3.7206573
B9: Ea_RWGS | C9: 81030 | D9: J/mol | K9: Ea_RWGS | L9: 97400 | M9: J/mol | S9: 88530
B10: Adsorption Constants | K10: Adsorption Constants | T10: Temperature | U10: 723 | V10: 773 | W10: 823 | X10: 873 | Y10: 923 | Z10: 973 | AA10: 1023 | AB10: 1073 | AC10: 1123 | AD10: 1173 | AE10: 1223 | AF10: 1273
A11: CH4 | B11: K_1 = K_CH4 | C11: 0.026 | D11: 1/bar | F11: K_CH4 | G11: =C11*EXP(-C12/($C$1*$C$2)) -> 3.1073041 | H11: 1/bar | J11: CH4 | K11: K_1 = K_CH4 | L11: 0.026 | M11: 1/bar | O11: K_CH4 | P11: =L11*EXP(-L12/($C$1*$C$2)) -> 0.45858473 | Q11: 1/bar | T11: K_CH4 | U11: =$L11*EXP(-$L12/($C$1*U$10)) -> 1.5087497 | V11: =$L11*EXP(-$L12/($C$1*V$10)) -> 1.1602173 | W11: =$L11*EXP(-$L12/($C$1*W$10)) -> 0.92113374 | X11: =$L11*EXP(-$L12/($C$1*X$10)) -> 0.75090607 | Y11: =$L11*EXP(-$L12/($C$1*Y$10)) -> 0.62583885 | Z11: =$L11*EXP(-$L12/($C$1*Z$10)) -> 0.53146088 | AA11: =$L11*EXP(-$L12/($C$1*AA$10)) -> 0.45858473 | AB11: =$L11*EXP(-$L12/($C$1*AB$10)) -> 0.40117817 | ... AF11: =$L11*EXP(-$L12/($C$1*AF$10)) -> 0.26099632
B12: dH_1=dH_CH4 | C12: -40684 | D12: J/mol | K12: dH_1=dH_CH4 | L12: =C12*0.6 -> -24410.4 | M12: J/mol | T12: K_CO2 | U12: =$L13*EXP(-$L14/($C$1*U$10)) -> 1.1178174 | V12: =$L13*EXP(-$L14/($C$1*V$10)) -> 0.87664867 | W12: =$L13*EXP(-$L14/($C$1*W$10)) -> 0.70811653 | X12: =$L13*EXP(-$L14/($C$1*X$10)) -> 0.58614469 | Y12: =$L13*EXP(-$L14/($C$1*Y$10)) -> 0.49522189 | Z12: =$L13*EXP(-$L14/($C$1*Z$10)) -> 0.42571453 | AA12: =$L13*EXP(-$L14/($C$1*AA$10)) -> 0.3714134 | AB12: =$L13*EXP(-$L14/($C$1*AB$10)) -> 0.32818565 | ... AF12: =$L13*EXP(-$L14/($C$1*AF$10)) -> 0.22048615
A13: CO2 | B13: K_2 = K_CO2 | C13: 0.0261 | D13: 1/bar | F13: K_CO2 | G13: =C13*EXP(-C14/($C$1*$C$2)) -> 2.1810667 | H13: 1/bar | J13: CO2 | K13: K_2 = K_CO2 | L13: 0.0261 | M13: 1/bar | O13: K_CO2 | P13: =L13*EXP(-L14/($C$1*$C$2)) -> 0.3714134 | Q13: 1/bar | T13: K_H2 | U13: =$L15*EXP(-$L16/($C$1*U$10)) -> 0.001470587 | V13: =$L15*EXP(-$L16/($C$1*V$10)) -> 0.0010648558 | W13: =$L15*EXP(-$L16/($C$1*W$10)) -> 0.00080191091 | X13: =$L15*EXP(-$L16/($C$1*X$10)) -> 0.00062383486 | Y13: =$L15*EXP(-$L16/($C$1*Y$10)) -> 0.00049868763 | Z13: =$L15*EXP(-$L16/($C$1*Z$10)) -> 0.0004079261 | AA13: =$L15*EXP(-$L16/($C$1*AA$10)) -> 0.00034030078 | AB13: =$L15*EXP(-$L16/($C$1*AB$10)) -> 0.00028872255 | ... AF13: =$L15*EXP(-$L16/($C$1*AF$10)) -> 0.00017022595
B14: dH_2=dH_CO2 | C14: -37641 | D14: J/mol | K14: dH_2=dH_CO2 | L14: =C14*0.6 -> -22584.6 | M14: J/mol | T14: K_CO | U14: =$L17*EXP(-$L18/($C$1*U$10)) -> 3.9254772e-05 | V14: =$L17*EXP(-$L18/($C$1*V$10)) -> 3.5931693e-05 | W14: =$L17*EXP(-$L18/($C$1*W$10)) -> 3.3245323e-05 | X14: =$L17*EXP(-$L18/($C$1*X$10)) -> 3.1034809e-05 | Y14: =$L17*EXP(-$L18/($C$1*Y$10)) -> 2.9188047e-05 | Z14: =$L17*EXP(-$L18/($C$1*Z$10)) -> 2.7624812e-05 | AA14: =$L17*EXP(-$L18/($C$1*AA$10)) -> 2.628636e-05 | AB14: =$L17*EXP(-$L18/($C$1*AB$10)) -> 2.5128798e-05 | ... AF14: =$L17*EXP(-$L18/($C$1*AF$10)) -> 2.1742078e-05
A15: H2 | B15: K_3 = K_H2 | C15: 1.494 | D15: 1/bar | F15: K_H2 | G15: =C15*EXP(-C16/($C$1*$C$2)) -> 3.0338894 | H15: 1/bar | J15: H2 | K15: K_3 = K_H2 | L15: 1e-05 | M15: 1/bar | O15: K_H2 | P15: =L15*EXP(-L16/($C$1*$C$2)) -> 0.00034030078 | Q15: 1/bar | T15: K_H2O | U15: =$L19*EXP(-$L20/($C$1*U$10)) -> 0.081878997 | V15: =$L19*EXP(-$L20/($C$1*V$10)) -> 0.043553754 | W15: =$L19*EXP(-$L20/($C$1*W$10)) -> 0.025014358 | X15: =$L19*EXP(-$L20/($C$1*X$10)) -> 0.015308771 | Y15: =$L19*EXP(-$L20/($C$1*Y$10)) -> 0.00988087 | Z15: =$L19*EXP(-$L20/($C$1*Z$10)) -> 0.0066710194 | AA15: =$L19*EXP(-$L20/($C$1*AA$10)) -> 0.0046802166 | AB15: =$L19*EXP(-$L20/($C$1*AB$10)) -> 0.0033937911 | ... AF15: =$L19*EXP(-$L20/($C$1*AF$10)) -> 0.0012078386
B16: dH_3=dH_H2 | C16: -6025 | D16: J/mol | K16: dH_3=dH_H2 | L16: -30000 | M16: J/mol
A17: CO2 | B17: K_-21 = K_CO | C17: 7.34e-06 | D17: 1/bar | F17: K_CO | G17: =C17*EXP(-C18/($C$1*$C$2)) -> 0.98191845 | H17: 1/bar | J17: CO2 | K17: K_-21 = K_CO | L17: 1e-05 | M17: 1/bar | O17: K_CO | P17: =L17*EXP(-L18/($C$1*$C$2)) -> 2.628636e-05 | Q17: 1/bar
B18: dH_-21=dH_CO | C18: -100395 | D18: J/mol | K18: dH_-21=dH_CO | L18: -8220 | M18: J/mol
A19: H2O | B19: K_-23 = K_H2O | C19: 4.73e-06 | D19: 1/bar | F19: K_H2O | G19: =C19*EXP(-C20/($C$1*$C$2)) -> 0.46473191 | H19: 1/bar | J19: H2O | K19: K_-23 = K_H2O | L19: 4.73e-06 | M19: 1/bar | O19: K_H2O | P19: =L19*EXP(-L20/($C$1*$C$2)) -> 0.0046802166 | Q19: 1/bar
B20: dH_-23=dH_H2O | C20: -97770 | D20: J/mol | K20: dH_-23=dH_H2O | L20: =C20*0.6 -> -58662 | M20: J/mol
B21: Equilibrium Constants | K21: Equilibrium Constants
B22: K4 = K_DRM | C22: 678000000000000 | F22: K_eq,DRM | G22: =C22*EXP(-C23/($C$1*$C$2)) -> 37.363302 | K22: K4 = K_DRM | L22: 678000000000000 | O22: K_eq,DRM | P22: =L22*EXP(-L23/($C$1*$C$2)) -> 37.363302
B23: dH_4 = dH_DRM | C23: 259660 | K23: dH_4 = dH_DRM | L23: 259660
B24: K_11 = K_RWGS | C24: 54.4971 | F24: K_eq,RWGS | G24: =C24*EXP(-C25/($C$1*$C$2)) -> 0.73879141 | K24: K_11 = K_RWGS | L24: 56.4971 | O24: K_eq,RWGS | P24: =L24*EXP(-L25/($C$1*$C$2)) -> 0.76590446
B25: dH_11 = dH_RWGS | C25: 36580 | K25: dH_11 = dH_RWGS | L25: 36580
A27: CARBON FORMATION AND GASIFICATION
A28: Benguerba et al. | J28: BEP Scaling
B29: Reaction Rate Constants | F29: CONSTANTS | K29: Reaction Rate Constants | O29: CONSTANTS
B30: A_crack | C30: 6950 | D30: mol/m3·s | F30: k_crack | G30: =C30*EXP(-C31/($C$1*$C$2)) -> 6.835726 | K30: A_crack | L30: 6950 | M30: mol/m3·s | O30: k_crack | P30: =L30*EXP(-L31/($C$1*$C$2)) -> 9.7416851e-05 | S30: 0.08
B31: Ea_crack | C31: 58893 | D31: J/mol | K31: Ea_crack | L31: 153800 | M31: J/mol | S31: 240000
B32: A_Boud | C32: 1.34e+15 | D32: mol/m3·s | F32: k_Boud | G32: =C32*EXP(-C33/($C$1*$C$2)) -> 474.655 | K32: A_Boud | L32: 1.34e+15 | M32: mol/m3·s | O32: k_Boud | P32: =L32*EXP(-L33/($C$1*$C$2)) -> 2.5378798e-08 | S32: 500000
B33: Ea_Boud | C33: 243835 | D33: J/mol | K33: Ea_Boud | L33: 445000 | M33: J/mol | S33: 175000
B34: A_gas | C34: 5550000000 | D34: mol/m3·s | K34: A_gas | L34: 5550000000 | M34: mol/m3·s | S34: 5550000000
B35: Ea_gas | C35: 166397 | D35: J/mol | K35: Ea_gas | L35: 166397 | M35: J/mol | S35: 166397
B36: Adsorption Constants | K36: Adsorption Constants
A37: C | B37: K_C | D37: 1/bar | F37: K_C | G37: =C37*EXP(-C38/($C$1*$C$2)) -> 0 | H37: 1/bar | J37: C | K37: K_C | M37: 1/bar | O37: K_C | P37: =L37*EXP(-L38/($C$1*$C$2)) -> 0 | Q37: 1/bar
B38: dH_C | D38: J/mol | K38: dH_C | M38: J/mol
B39: Equilibrium Constants | K39: Equilibrium Constants
B40: K_crack | C40: 2.98e-05 | F40: K_eq,crack | G40: =C40*EXP(-C41/($C$1*$C$2)) -> 1.4538938e-09 | K40: K_crack | L40: 298000 | O40: K_eq,crack | P40: =L40*EXP(-L41/($C$1*$C$2)) -> 14.538938 | S40: 298000
B41: dH_crack | C41: 84440 | K41: dH_crack | L41: 84440 | S41: 84440
...

Sheet BEP
A1: S | B1: 0.6
A2: alfa | B2: 0.5
A7: DRM
A8: Step4 (i=4) | B8: dH_Ni | C8: dH_gas | D8: dH_Sn | E8: ddH | F8: E_a,Sn
B9: -35 | C9: 439.6 | D9: =C9+$B$1*(B9-C9) -> 154.84 | E9: =D9-B9 -> 189.84 | F9: =('Domain-Shift'!C7)/1000+$B$2*E9 -> 196.985 | G9: kJ/mol
A11: RWGS
A12: Step4 (i=11) | B12: dH_Ni | C12: dH_gas | D12: dH_Sn | E12: ddH | F12: E_a,Sn
B13: -38 | C13: 43.8 | D13: =C13+$B$1*(B13-C13) -> -5.28 | E13: =D13-B13 -> 32.72 | F13: =('Domain-Shift'!C9)/1000+$B$2*E13 -> 97.39 | G13: kJ/mol
A15: Crack
A16: Step4 (i=4) | B16: dH_Ni | C16: dH_gas | D16: dH_Sn | E16: ddH | F16: E_a,Sn
B17: -35 | C17: 439.6 | D17: =C17+$B$1*(B17-C17) -> 154.84 | E17: =D17-B17 -> 189.84 | F17: =('Domain-Shift'!C31)/1000+$B$2*E17 -> 153.813 | G17: kJ/mol
A19: Boud
A20: Step4 (i=4) | B20: dH_Ni | C20: dH_gas | D20: dH_Sn | E20: ddH | F20: E_a,Sn
B21: -35 | C21: 439.6 | D21: =C21+$B$1*(B21-C21) -> 154.84 | E21: =D21-B21 -> 189.84 | F21: =('Domain-Shift'!C33)/1000+$B$2*E21 -> 338.755 | G21: kJ/mol

Sheet Surface Renewal
A1: SURFACE RENEWAL DYNAMICS AND EFFECTIVE SITE VACANCY
A2: Parameter | B2: Min | C2: Max
A3: u_s | B3: =0.001 -> 0.001 | C3: =0.01 -> 0.01 | D3: m/s
A4: L_s | B4: =0.01 -> 0.01 | C4: =0.1 -> 0.1 | D4: m
A5: s | B5: 30 | C5: 80 | D5: 1/s
A7: \upsilon | B7: =10000000000000 -> 10000000000000 | C7: 1/s
A8: \theta | B8: 1
A9: E_des | B9: |dH_ads| | C9: from "Kinetic parameters"
A10: R | B10: 8.314 | C10: J/mol·K
A12: Calculo k_des:
B13: 723 | C13: 773 | D13: 823 | E13: 873 | F13: 923 | G13: 973 | H13: 1023 | I13: 1073 | J13: 1123 | K13: 1173 | L13: 1223 | M13: 1273 | N13: 1323
A14: Temp. [K] | B14: 723 | C14: 773 | D14: 823 | E14: 873 | F14: 923 | G14: 973 | H14: 1023 | I14: 1073 | J14: 1123 | K14: 1173 | L14: 1223 | M14: 1273 | N14: 1323
A15: k_des_CH4 | B15: =$B$7*$B$8*EXP(-(ABS('Kinetic parameters'!$B17))/($B$10*B$13)) -> 1.7232812e+11 | C15: =$B$7*$B$8*EXP(-(ABS('Kinetic parameters'!$B17))/($B$10*C$13)) -> 2.2409595e+11 | D15: =$B$7*$B$8*EXP(-(ABS('Kinetic parameters'!$B17))/($B$10*D$13)) -> 2.8226086e+11 | E15: =$B$7*$B$8*EXP(-(ABS('Kinetic parameters'!$B17))/($B$10*E$13)) -> 3.4624837e+11 | F15: =$B$7*$B$8*EXP(-(ABS('Kinetic parameters'!$B17))/($B$10*F$13)) -> 4.1544241e+11 | G15: =$B$7*$B$8*EXP(-(ABS('Kinetic parameters'!$B17))/($B$10*G$13)) -> 4.8921757e+11 | H15: =$B$7*$B$8*EXP(-(ABS('Kinetic parameters'!$B17))/($B$10*H$13)) -> 5.6696174e+11 | I15: =$B$7*$B$8*EXP(-(ABS('Kinetic parameters'!$B17))/($B$10*I$13)) -> 6.480911e+11 | ... N15: =$B$7*$B$8*EXP(-(ABS('Kinetic parameters'!$B17))/($B$10*N$13)) -> 1.0869126e+12 | O15: 1/s
A16: k_des_CO2 | B16: =$B$7*$B$8*EXP(-(ABS('Kinetic parameters'!$B19))/($B$10*B$13)) -> 2.3349072e+11 | C16: =$B$7*$B$8*EXP(-(ABS('Kinetic parameters'!$B19))/($B$10*C$13)) -> 2.9772474e+11 | D16: =$B$7*$B$8*EXP(-(ABS('Kinetic parameters'!$B19))/($B$10*D$13)) -> 3.685834e+11 | E16: =$B$7*$B$8*EXP(-(ABS('Kinetic parameters'!$B19))/($B$10*E$13)) -> 4.4528255e+11 | F16: =$B$7*$B$8*EXP(-(ABS('Kinetic parameters'!$B19))/($B$10*F$13)) -> 5.2703648e+11 | G16: =$B$7*$B$8*EXP(-(ABS('Kinetic parameters'!$B19))/($B$10*G$13)) -> 6.130869e+11 | H16: =$B$7*$B$8*EXP(-(ABS('Kinetic parameters'!$B19))/($B$10*H$13)) -> 7.02721e+11 | I16: =$B$7*$B$8*EXP(-(ABS('Kinetic parameters'!$B19))/($B$10*I$13)) -> 7.9528156e+11 | ... N16: =$B$7*$B$8*EXP(-(ABS('Kinetic parameters'!$B19))/($B$10*N$13)) -> 1.2831677e+12 | O16: 1/s
A17: k_des_H2 | B17: =$B$7*$B$8*EXP(-(ABS('Kinetic parameters'!$B21))/($B$10*B$13)) -> 6.8000056e+10 | C17: =$B$7*$B$8*EXP(-(ABS('Kinetic parameters'!$B21))/($B$10*C$13)) -> 9.3909427e+10 | D17: =$B$7*$B$8*EXP(-(ABS('Kinetic parameters'!$B21))/($B$10*D$13)) -> 1.2470213e+11 | E17: =$B$7*$B$8*EXP(-(ABS('Kinetic parameters'!$B21))/($B$10*E$13)) -> 1.6029883e+11 | F17: =$B$7*$B$8*EXP(-(ABS('Kinetic parameters'!$B21))/($B$10*F$13)) -> 2.0052633e+11 | G17: =$B$7*$B$8*EXP(-(ABS('Kinetic parameters'!$B21))/($B$10*G$13)) -> 2.4514244e+11 | H17: =$B$7*$B$8*EXP(-(ABS('Kinetic parameters'!$B21))/($B$10*H$13)) -> 2.9385768e+11 | I17: =$B$7*$B$8*EXP(-(ABS('Kinetic parameters'!$B21))/($B$10*I$13)) -> 3.4635327e+11 | ... N17: =$B$7*$B$8*EXP(-(ABS('Kinetic parameters'!$B21))/($B$10*N$13)) -> 6.5388032e+11 | O17: 1/s
A18: k_des_CO | B18: =$B$7*$B$8*EXP(-(ABS('Kinetic parameters'!$B23))/($B$10*B$13)) -> 2.547461e+12 | C18: =$B$7*$B$8*EXP(-(ABS('Kinetic parameters'!$B23))/($B$10*C$13)) -> 2.7830584e+12 | D18: =$B$7*$B$8*EXP(-(ABS('Kinetic parameters'!$B23))/($B$10*D$13)) -> 3.0079419e+12 | E18: =$B$7*$B$8*EXP(-(ABS('Kinetic parameters'!$B23))/($B$10*E$13)) -> 3.2221883e+12 | F18: =$B$7*$B$8*EXP(-(ABS('Kinetic parameters'!$B23))/($B$10*F$13)) -> 3.42606e+12 | G18: =$B$7*$B$8*EXP(-(ABS('Kinetic parameters'!$B23))/($B$10*G$13)) -> 3.6199341e+12 | H18: =$B$7*$B$8*EXP(-(ABS('Kinetic parameters'!$B23))/($B$10*H$13)) -> 3.8042544e+12 | I18: =$B$7*$B$8*EXP(-(ABS('Kinetic parameters'!$B23))/($B$10*I$13)) -> 3.979498e+12 | ... N18: =$B$7*$B$8*EXP(-(ABS('Kinetic parameters'!$B23))/($B$10*N$13)) -> 4.7363798e+12 | O18: 1/s
A19: k_des_H2O | B19: =$B$7*$B$8*EXP(-(ABS('Kinetic parameters'!$B25))/($B$10*B$13)) -> 5.7768172e+08 | C19: =$B$7*$B$8*EXP(-(ABS('Kinetic parameters'!$B25))/($B$10*C$13)) -> 1.0860143e+09 | D19: =$B$7*$B$8*EXP(-(ABS('Kinetic parameters'!$B25))/($B$10*D$13)) -> 1.890914e+09 | E19: =$B$7*$B$8*EXP(-(ABS('Kinetic parameters'!$B25))/($B$10*E$13)) -> 3.0897321e+09 | F19: =$B$7*$B$8*EXP(-(ABS('Kinetic parameters'!$B25))/($B$10*F$13)) -> 4.7870279e+09 | G19: =$B$7*$B$8*EXP(-(ABS('Kinetic parameters'!$B25))/($B$10*G$13)) -> 7.0903707e+09 | H19: =$B$7*$B$8*EXP(-(ABS('Kinetic parameters'!$B25))/($B$10*H$13)) -> 1.010637e+10 | I19: =$B$7*$B$8*EXP(-(ABS('Kinetic parameters'!$B25))/($B$10*I$13)) -> 1.3937216e+10 | ... N19: =$B$7*$B$8*EXP(-(ABS('Kinetic parameters'!$B25))/($B$10*N$13)) -> 4.8286453e+10 | O19: 1/s
A21: Calculo Da_s:
A22: Extr. Min. s | B22: 0.1 | C22: 1/s
B23: 723 | C23: 773 | D23: 823 | E23: 873 | F23: 923 | G23: 973 | H23: 1023 | I23: 1073 | J23: 1123 | K23: 1173 | L23: 1223 | M23: 1273 | N23: 1323
A24: Temp. [K] | B24: 723 | C24: 773 | D24: 823 | E24: 873 | F24: 923 | G24: 973 | H24: 1023 | I24: 1073 | J24: 1123 | K24: 1173 | L24: 1223 | M24: 1273 | N24: 1323
A25: k_des_CH4 | B25: =$B$22/B15 -> 5.8028836e-13 | C25: =$B$22/C15 -> 4.4623742e-13 | D25: =$B$22/D15 -> 3.5428221e-13 | E25: =$B$22/E15 -> 2.8881003e-13 | F25: =$B$22/F15 -> 2.4070725e-13 | G25: =$B$22/G15 -> 2.0440803e-13 | H25: =$B$22/H15 -> 1.7637874e-13 | I25: =$B$22/I15 -> 1.5429929e-13 | ... N25: =$B$22/N15 -> 9.2003717e-14
A26: k_des_CO2 | B26: =$B$22/B16 -> 4.2828254e-13 | C26: =$B$22/C16 -> 3.3588071e-13 | D26: =$B$22/D16 -> 2.7130902e-13 | E26: =$B$22/E16 -> 2.2457651e-13 | F26: =$B$22/F16 -> 1.8974019e-13 | G26: =$B$22/G16 -> 1.6310901e-13 | H26: =$B$22/H16 -> 1.4230399e-13 | I26: =$B$22/I16 -> 1.2574163e-13 | ... N26: =$B$22/N16 -> 7.7932139e-14
A27: k_des_H2 | B27: =$B$22/B17 -> 1.470587e-12 | C27: =$B$22/C17 -> 1.0648558e-12 | D27: =$B$22/D17 -> 8.0191091e-13 | E27: =$B$22/E17 -> 6.2383486e-13 | F27: =$B$22/F17 -> 4.9868763e-13 | G27: =$B$22/G17 -> 4.079261e-13 | H27: =$B$22/H17 -> 3.4030078e-13 | I27: =$B$22/I17 -> 2.8872255e-13 | ... N27: =$B$22/N17 -> 1.5293319e-13
A28: k_des_CO | B28: =$B$22/B18 -> 3.9254772e-14 | C28: =$B$22/C18 -> 3.5931693e-14 | D28: =$B$22/D18 -> 3.3245323e-14 | E28: =$B$22/E18 -> 3.1034809e-14 | F28: =$B$22/F18 -> 2.9188047e-14 | G28: =$B$22/G18 -> 2.7624812e-14 | H28: =$B$22/H18 -> 2.628636e-14 | I28: =$B$22/I18 -> 2.5128798e-14 | ... N28: =$B$22/N18 -> 2.1113172e-14
A29: k_des_H2O | B29: =$B$22/B19 -> 1.731057e-10 | C29: =$B$22/C19 -> 9.2079818e-11 | D29: =$B$22/D19 -> 5.2884477e-11 | E29: =$B$22/E19 -> 3.2365266e-11 | F29: =$B$22/F19 -> 2.0889788e-11 | G29: =$B$22/G19 -> 1.4103635e-11 | H29: =$B$22/H19 -> 9.8947497e-12 | I29: =$B$22/I19 -> 7.1750341e-12 | ... N29: =$B$22/N19 -> 2.0709742e-12
A31: Valor medio s | B31: =(B5+C5)/2 -> 55 | C31: 1/s
B32: 723 | C32: 773 | D32: 823 | E32: 873 | F32: 923 | G32: 973 | H32: 1023 | I32: 1073 | J32: 1123 | K32: 1173 | L32: 1223 | M32: 1273 | N32: 1323
A33: Temp. [K] | B33: 723 | C33: 773 | D33: 823 | E33: 873 | F33: 923 | G33: 973 | H33: 1023 | I33: 1073 | J33: 1123 | K33: 1173 | L33: 1223 | M33: 1273 | N33: 1323
A34: k_des_CH4 | B34: =$B$31/B15 -> 3.191586e-10 | C34: =$B$31/C15 -> 2.4543058e-10 | D34: =$B$31/D15 -> 1.9485521e-10 | E34: =$B$31/E15 -> 1.5884551e-10 | F34: =$B$31/F15 -> 1.3238899e-10 | G34: =$B$31/G15 -> 1.1242442e-10 | H34: =$B$31/H15 -> 9.7008309e-11 | I34: =$B$31/I15 -> 8.4864612e-11 | ... N34: =$B$31/N15 -> 5.0602044e-11
A35: k_des_CO2 | B35: =$B$31/B16 -> 2.355554e-10 | C35: =$B$31/C16 -> 1.8473439e-10 | D35: =$B$31/D16 -> 1.4921996e-10 | E35: =$B$31/E16 -> 1.2351708e-10 | F35: =$B$31/F16 -> 1.043571e-10 | G35: =$B$31/G16 -> 8.9709958e-11 | H35: =$B$31/H16 -> 7.8267192e-11 | I35: =$B$31/I16 -> 6.9157896e-11 | ... N35: =$B$31/N16 -> 4.2862677e-11
A36: k_des_H2 | B36: =$B$31/B17 -> 8.0882286e-10 | C36: =$B$31/C17 -> 5.856707e-10 | D36: =$B$31/D17 -> 4.41051e-10 | E36: =$B$31/E17 -> 3.4310917e-10 | F36: =$B$31/F17 -> 2.742782e-10 | G36: =$B$31/G17 -> 2.2435936e-10 | H36: =$B$31/H17 -> 1.8716543e-10 | I36: =$B$31/I17 -> 1.587974e-10 | ... N36: =$B$31/N17 -> 8.4113252e-11
A37: k_des_CO | B37: =$B$31/B18 -> 2.1590125e-11 | C37: =$B$31/C18 -> 1.9762431e-11 | D37: =$B$31/D18 -> 1.8284928e-11 | E37: =$B$31/E18 -> 1.7069145e-11 | F37: =$B$31/F18 -> 1.6053426e-11 | G37: =$B$31/G18 -> 1.5193647e-11 | H37: =$B$31/H18 -> 1.4457498e-11 | I37: =$B$31/I18 -> 1.3820839e-11 | ... N37: =$B$31/N18 -> 1.1612244e-11
A38: k_des_H2O | B38: =$B$31/B19 -> 9.5208136e-08 | C38: =$B$31/C19 -> 5.06439e-08 | D38: =$B$31/D19 -> 2.9086462e-08 | E38: =$B$31/E19 -> 1.7800896e-08 | F38: =$B$31/F19 -> 1.1489384e-08 | G38: =$B$31/G19 -> 7.7569993e-09 | H38: =$B$31/H19 -> 5.4421123e-09 | I38: =$B$31/I19 -> 3.9462688e-09 | ... N38: =$B$31/N19 -> 1.1390358e-09

Sheet Mass Transfer 
A1: INTERFACIAL MASS TRANSFER AT THE GAS-LIQUID METAL BOUNDARY
A2: Parameter | B2: Min | C2: Max | E2: Units
A3: D_LM | B3: 1e-09 | C3: 1e-08 | E3: m2/s
A4: s | B4: ='Surface Renewal'!C5 -> 80 | C4: =(B4+D4)/2 -> 55 | D4: ='Surface Renewal'!B5 -> 30 | E4: 1/s
A5: k_L | B5: =SQRT($B$3*B4) -> 0.00028284271 | C5: =SQRT($B$3*C4) -> 0.00023452079 | D5: =SQRT($B$3*D4) -> 0.00017320508 | E5: m/s
B6: =SQRT($C$3*B4) -> 0.00089442719 | C6: =SQRT($C$3*C4) -> 0.00074161985 | D6: =SQRT($C$3*D4) -> 0.00054772256
A8: Número de Hatta
A9: k_rxn | B9: =10^2 -> 100 | C9: =10^4 -> 10000 | D9: 1/s | E9: ='Kinetic parameters'!F7*'Kinetic parameters'!H16*B10*'Kinetic parameters'!B3*'Kinetic parameters'!B5/(B11^2) -> 0.032650074 | F9: ='Kinetic parameters'!F7*'Kinetic parameters'!H16*C10*'Kinetic parameters'!B3*'Kinetic parameters'!B5/(B11^2) -> 0.83584189 | L9: Ha = 50 | M9: Ha = 11,18 | N9: Ha =5,8 | O9: Ha =3,53 | P9: Ha =3,53 | Q9: Ha = 0,351
A10: Dens_cat | B10: 250 | C10: 6400 | D10: kg/m3 | L10: DLM = 1·10-8 | M10: DLM = 1·10-8 | N10: DLM = 1·10-8 | O10: DLM = 1·10-9 | P10: DLM = 1·10-8 | Q10: DLM = 1·10-9
A11: Omega | B11: 1.5 | L11: krxn = 1·104 | M11: krxn = 1·104 | N11: krxn = 1·102 | O11: krxn = 1·104 | P11: krxn = 1·102 | Q11: krxn = 1·102
A12: Ha | B12: =SQRT($B$9*$B$3)/B5 -> 1.118034 | C12: =SQRT($B$9*$B$3)/C5 -> 1.3483997 | D12: =SQRT($B$9*$B$3)/D5 -> 1.8257419 | E12: =SQRT($B$9*$C$3)/B5 -> 3.5355339 | F12: =SQRT($B$9*$C$3)/C5 -> 4.2640143 | G12: =SQRT($B$9*$C$3)/D5 -> 5.7735027 | L12: kL = 2·10-4 | M12: kL = 9·10-4 | N12: kL = 9·10-4 | O12: kL = 9·10-4 | P12: kL = 3·10-4 | Q12: kL = 9·10-4
A13: =SQRT($C$9*$C$3)/0.0002 -> 50 | B13: =SQRT($B$9*$B$3)/B6 -> 0.35355339 | C13: =SQRT($B$9*$B$3)/C6 -> 0.42640143 | D13: =SQRT($B$9*$B$3)/D6 -> 0.57735027 | E13: =SQRT($B$9*$C$3)/B6 -> 1.118034 | F13: =SQRT($B$9*$C$3)/C6 -> 1.3483997 | G13: =SQRT($B$9*$C$3)/D6 -> 1.8257419 | L13: η_GL​=0,02 | M13: η_GL​=0,09 | N13: η_GL​=0,282 | O13: η_GL​=0,282 | P13: η_GL​=0,282 | Q13: η_GL​=0,961
A14: =SQRT($B$9*$B$3)/0.0009 -> 0.35136418 | B14: =SQRT($C$9*$B$3)/B5 -> 11.18034 | C14: =SQRT($C$9*$B$3)/C5 -> 13.483997 | D14: =SQRT($C$9*$B$3)/D5 -> 18.257419 | E14: =SQRT($C$9*$C$3)/B5 -> 35.355339 | F14: =SQRT($C$9*$C$3)/C5 -> 42.640143 | G14: =SQRT($C$9*$C$3)/D5 -> 57.735027
B15: =SQRT($C$9*$B$3)/B6 -> 3.5355339 | C15: =SQRT($C$9*$B$3)/C6 -> 4.2640143 | D15: =SQRT($C$9*$B$3)/D6 -> 5.7735027 | E15: =SQRT($C$9*$C$3)/B6 -> 11.18034 | F15: =SQRT($C$9*$C$3)/C6 -> 13.483997 | G15: =SQRT($C$9*$C$3)/D6 -> 18.257419
A17: El numero de Hatta se sitúa entre 50 y 0,35
A19: η_GL​
A20: η_GL​ | B20: =TANH(B12)/B12 -> 0.72169898 | C20: =TANH(C12)/C12 -> 0.64793475 | D20: =TANH(D12)/D12 -> 0.52001207 | E20: =TANH(E12)/E12 -> 0.28236267 | F20: =TANH(F12)/F12 -> 0.23442801 | G20: =TANH(G12)/G12 -> 0.17320173
A21: =TANH(A13)/A13 -> 0.02 | B21: =TANH(B13)/B13 -> 0.96031634 | C21: =TANH(C13)/C13 -> 0.94349953 | D21: =TANH(D13)/D13 -> 0.90194274 | E21: =TANH(E13)/E13 -> 0.72169898 | F21: =TANH(F13)/F13 -> 0.64793475 | G21: =TANH(G13)/G13 -> 0.52001207
A22: =TANH(A14)/A14 -> 0.96078323 | B22: =TANH(B14)/B14 -> 0.089442719 | C22: =TANH(C14)/C14 -> 0.074161985 | D22: =TANH(D14)/D14 -> 0.054772256 | E22: =TANH(E14)/E14 -> 0.028284271 | F22: =TANH(F14)/F14 -> 0.023452079 | G22: =TANH(G14)/G14 -> 0.017320508
B23: =TANH(B15)/B15 -> 0.28236267 | C23: =TANH(C15)/C15 -> 0.23442801 | D23: =TANH(D15)/D15 -> 0.17320173 | E23: =TANH(E15)/E15 -> 0.089442719 | F23: =TANH(F15)/F15 -> 0.074161985 | G23: =TANH(G15)/G15 -> 0.054772256

Sheet Ads equilibria Ω
B1: R= | C1: 8.314 | D1: J/mol K
B2: T= | C2: 773 | D2: K
B3: Adsorption Constants | F3: CONSTANTS | K3: Inlet | L3: =L4-273 -> 450 | M3: =M4-273 -> 500 | N3: =N4-273 -> 550 | O3: =O4-273 -> 600 | P3: =P4-273 -> 650 | Q3: =Q4-273 -> 700 | R3: =R4-273 -> 750 | S3: =S4-273 -> 800 | ... W3: =W4-273 -> 1000
A4: CH4 | B4: K_1 = K_CH4 | C4: ='Domain-Shift'!L11 -> 0.026 | D4: 1/bar | F4: K_CH4 | G4: =C4*EXP(-C5/($C$1*$C$2)) -> 1.1602173 | H4: 1/bar | K4: Temperature | L4: 723 | M4: 773 | N4: 823 | O4: 873 | P4: 923 | Q4: 973 | R4: 1023 | S4: 1073 | T4: 1123 | U4: 1173 | V4: 1223 | W4: 1273
B5: dH_1=dH_CH4 | C5: ='Domain-Shift'!L12 -> -24410.4 | D5: J/mol | K5: K_CH4*P_CH4 | L5: =($C4*EXP(-$C5/($C$1*L$4)))*$C18 -> 0.75437486 | M5: =($C4*EXP(-$C5/($C$1*M$4)))*$C18 -> 0.58010865 | N5: =($C4*EXP(-$C5/($C$1*N$4)))*$C18 -> 0.46056687 | O5: =($C4*EXP(-$C5/($C$1*O$4)))*$C18 -> 0.37545303 | P5: =($C4*EXP(-$C5/($C$1*P$4)))*$C18 -> 0.31291943 | Q5: =($C4*EXP(-$C5/($C$1*Q$4)))*$C18 -> 0.26573044 | R5: =($C4*EXP(-$C5/($C$1*R$4)))*$C18 -> 0.22929237 | S5: =($C4*EXP(-$C5/($C$1*S$4)))*$C18 -> 0.20058908 | ... W5: =($C4*EXP(-$C5/($C$1*W$4)))*$C18 -> 0.13049816
A6: CO2 | B6: K_2 = K_CO2 | C6: ='Domain-Shift'!L13 -> 0.0261 | D6: 1/bar | F6: K_CO2 | G6: =C6*EXP(-C7/($C$1*$C$2)) -> 0.87664867 | H6: 1/bar | K6: K_CO2*P_CO2 | L6: =($C6*EXP(-$C7/($C$1*L$4)))*$C19 -> 0.55890872 | M6: =($C6*EXP(-$C7/($C$1*M$4)))*$C19 -> 0.43832433 | N6: =($C6*EXP(-$C7/($C$1*N$4)))*$C19 -> 0.35405827 | O6: =($C6*EXP(-$C7/($C$1*O$4)))*$C19 -> 0.29307234 | P6: =($C6*EXP(-$C7/($C$1*P$4)))*$C19 -> 0.24761095 | Q6: =($C6*EXP(-$C7/($C$1*Q$4)))*$C19 -> 0.21285726 | R6: =($C6*EXP(-$C7/($C$1*R$4)))*$C19 -> 0.1857067 | S6: =($C6*EXP(-$C7/($C$1*S$4)))*$C19 -> 0.16409283 | ... W6: =($C6*EXP(-$C7/($C$1*W$4)))*$C19 -> 0.11024308
B7: dH_2=dH_CO2 | C7: ='Domain-Shift'!L14 -> -22584.6 | D7: J/mol | K7: sqrt(K_H2*P_H2) | L7: =SQRT(($C8*EXP(-$C9/($C$1*L$4)))*$C20) -> 0 | M7: =SQRT(($C8*EXP(-$C9/($C$1*M$4)))*$C20) -> 0 | N7: =SQRT(($C8*EXP(-$C9/($C$1*N$4)))*$C20) -> 0 | O7: =SQRT(($C8*EXP(-$C9/($C$1*O$4)))*$C20) -> 0 | P7: =SQRT(($C8*EXP(-$C9/($C$1*P$4)))*$C20) -> 0 | Q7: =SQRT(($C8*EXP(-$C9/($C$1*Q$4)))*$C20) -> 0 | R7: =SQRT(($C8*EXP(-$C9/($C$1*R$4)))*$C20) -> 0 | S7: =SQRT(($C8*EXP(-$C9/($C$1*S$4)))*$C20) -> 0 | ... W7: =SQRT(($C8*EXP(-$C9/($C$1*W$4)))*$C20) -> 0
A8: H2 | B8: K_3 = K_H2 | C8: ='Domain-Shift'!L15 -> 1e-05 | D8: 1/bar | F8: K_H2 | G8: =C8*EXP(-C9/($C$1*$C$2)) -> 0.0010648558 | H8: 1/bar | K8: K_CO*P_CO | L8: =($C10*EXP(-$C11/($C$1*L$4)))*$C21 -> 0 | M8: =($C10*EXP(-$C11/($C$1*M$4)))*$C21 -> 0 | N8: =($C10*EXP(-$C11/($C$1*N$4)))*$C21 -> 0 | O8: =($C10*EXP(-$C11/($C$1*O$4)))*$C21 -> 0 | P8: =($C10*EXP(-$C11/($C$1*P$4)))*$C21 -> 0 | Q8: =($C10*EXP(-$C11/($C$1*Q$4)))*$C21 -> 0 | R8: =($C10*EXP(-$C11/($C$1*R$4)))*$C21 -> 0 | S8: =($C10*EXP(-$C11/($C$1*S$4)))*$C21 -> 0 | ... W8: =($C10*EXP(-$C11/($C$1*W$4)))*$C21 -> 0
B9: dH_3=dH_H2 | C9: ='Domain-Shift'!L16 -> -30000 | D9: J/mol | K9: K_H2O*P_H2O | L9: =($C12*EXP(-$C13/($C$1*L$4)))*$C22 -> 0 | M9: =($C12*EXP(-$C13/($C$1*M$4)))*$C22 -> 0 | N9: =($C12*EXP(-$C13/($C$1*N$4)))*$C22 -> 0 | O9: =($C12*EXP(-$C13/($C$1*O$4)))*$C22 -> 0 | P9: =($C12*EXP(-$C13/($C$1*P$4)))*$C22 -> 0 | Q9: =($C12*EXP(-$C13/($C$1*Q$4)))*$C22 -> 0 | R9: =($C12*EXP(-$C13/($C$1*R$4)))*$C22 -> 0 | S9: =($C12*EXP(-$C13/($C$1*S$4)))*$C22 -> 0 | ... W9: =($C12*EXP(-$C13/($C$1*W$4)))*$C22 -> 0
A10: CO2 | B10: K_-21 = K_CO | C10: ='Domain-Shift'!L17 -> 1e-05 | D10: 1/bar | F10: K_CO | G10: =C10*EXP(-C11/($C$1*$C$2)) -> 3.5931693e-05 | H10: 1/bar | K10: Ω_total | L10: =1+SUM(L5:L9) -> 2.3132836 | M10: =1+SUM(M5:M9) -> 2.018433 | N10: =1+SUM(N5:N9) -> 1.8146251 | O10: =1+SUM(O5:O9) -> 1.6685254 | P10: =1+SUM(P5:P9) -> 1.5605304 | Q10: =1+SUM(Q5:Q9) -> 1.4785877 | R10: =1+SUM(R5:R9) -> 1.4149991 | S10: =1+SUM(S5:S9) -> 1.3646819 | ... W10: =1+SUM(W5:W9) -> 1.2407412
B11: dH_-21=dH_CO | C11: ='Domain-Shift'!L18 -> -8220 | D11: J/mol | K11: (Ω_total)^2 | L11: =L10^2 -> 5.3512809 | M11: =M10^2 -> 4.0740717 | N11: =N10^2 -> 3.2928644 | O11: =O10^2 -> 2.7839769 | P11: =P10^2 -> 2.435255 | Q11: =Q10^2 -> 2.1862216 | R11: =R10^2 -> 2.0022224 | S11: =S10^2 -> 1.8623567 | ... W11: =W10^2 -> 1.5394388
A12: H2O | B12: K_-23 = K_H2O | C12: ='Domain-Shift'!L19 -> 4.73e-06 | D12: 1/bar | F12: K_H2O | G12: =C12*EXP(-C13/($C$1*$C$2)) -> 0.043553754 | H12: 1/bar | L12: =1/L11 -> 0.18687115 | M12: =1/M11 -> 0.24545469 | N12: =1/N11 -> 0.30368697 | O12: =1/O11 -> 0.35919838 | P12: =1/P11 -> 0.41063461 | Q12: =1/Q11 -> 0.45741017 | R12: =1/R11 -> 0.49944503 | S12: =1/S11 -> 0.53695406 | ... W12: =1/W11 -> 0.64958736
B13: dH_-23=dH_H2O | C13: ='Domain-Shift'!L20 -> -58662 | D13: J/mol | K13: Outlet
K14: Temperature | L14: 723 | M14: 773 | N14: 823 | O14: 873 | P14: 923 | Q14: 973 | R14: 1023 | S14: 1073 | T14: 1123 | U14: 1173 | V14: 1223 | W14: 1273
K15: K_CH4*P_CH4 | L15: =($C4*EXP(-$C5/($C$1*L$14)))*L$26 -> 0.76412955 | M15: =($C4*EXP(-$C5/($C$1*M$14)))*M$26 -> 0.58671869 | N15: =($C4*EXP(-$C5/($C$1*N$14)))*N$26 -> 0.46137157 | O15: =($C4*EXP(-$C5/($C$1*O$14)))*O$26 -> 0.35925215 | P15: =($C4*EXP(-$C5/($C$1*P$14)))*P$26 -> 0.25090105 | Q15: =($C4*EXP(-$C5/($C$1*Q$14)))*Q$26 -> 0.12595851 | R15: =($C4*EXP(-$C5/($C$1*R$14)))*R$26 -> 0.036708671 | S15: =($C4*EXP(-$C5/($C$1*S$14)))*S$26 -> 0.010497245 | ... W15: =($C4*EXP(-$C5/($C$1*W$14)))*W$26 -> 0.00089604305 | AF15: $0,658$ | AG15: $0,439$ | AH15: $0,276$ | AI15: $0,158$ | AJ15: $0,082$ | AK15: $0,040$ | AL15: $0,019$ | AM15: $9,27\cdot 10^{-3}$ | AN15: $4,92\cdot 10^{-3}$ | AO15: $2,83\cdot 10^{-3}$ | AP15: $1,95\cdot 10^{-3}$ | AQ15: $1,29\cdot 10^{-3}$
B16: PARTIAL PRESSURES | F16: K_i*P_i | K16: K_CO2*P_CO2 | L16: =($C6*EXP(-$C7/($C$1*L$14)))*L$27 -> 0.56590438 | M16: =($C6*EXP(-$C7/($C$1*M$14)))*M$27 -> 0.44250935 | N16: =($C6*EXP(-$C7/($C$1*N$14)))*N$27 -> 0.35091598 | O16: =($C6*EXP(-$C7/($C$1*O$14)))*O$27 -> 0.26770484 | P16: =($C6*EXP(-$C7/($C$1*P$14)))*P$27 -> 0.17180028 | Q16: =($C6*EXP(-$C7/($C$1*Q$14)))*Q$27 -> 0.073305709 | R16: =($C6*EXP(-$C7/($C$1*R$14)))*R$27 -> 0.017901473 | S16: =($C6*EXP(-$C7/($C$1*S$14)))*S$27 -> 0.0045441402 | ... W16: =($C6*EXP(-$C7/($C$1*W$14)))*W$27 -> 0.00027356265
B17: Inlet | K17: sqrt(K_H2*P_H2) | L17: =SQRT(($C8*EXP(-$C9/($C$1*L$14)))*L$28) -> 3.8934253e-05 | M17: =SQRT(($C8*EXP(-$C9/($C$1*M$14)))*M$28) -> 0.00013785999 | N17: =SQRT(($C8*EXP(-$C9/($C$1*N$14)))*N$28) -> 0.00059569491 | O17: =SQRT(($C8*EXP(-$C9/($C$1*O$14)))*O$28) -> 0.0020132055 | P17: =SQRT(($C8*EXP(-$C9/($C$1*P$14)))*P$28) -> 0.0050792313 | Q17: =SQRT(($C8*EXP(-$C9/($C$1*Q$14)))*Q$28) -> 0.0091404329 | R17: =SQRT(($C8*EXP(-$C9/($C$1*R$14)))*R$28) -> 0.011589911 | S17: =SQRT(($C8*EXP(-$C9/($C$1*S$14)))*S$28) -> 0.011625929 | ... W17: =SQRT(($C8*EXP(-$C9/($C$1*W$14)))*W$28) -> 0.0092348816 | AF17: $0,463$ | AG17: $0,300$ | AH17: $0,181$ | AI17: $9,70\cdot 10^{-2}$ | AJ17: $4,70\cdot 10^{-2}$ | AK17: $2,10\cdot 10^{-2}$ | AL17: $8,92\cdot 10^{-3}$ | AM17: $4,00\cdot 10^{-3}$ | AN17: $1,94\cdot 10^{-3}$ | AO17: $9,37\cdot 10^{-4}$ | AP17: $4,27\cdot 10^{-4}$ | AQ17: $1,89\cdot 10^{-4}$
B18: P_CH4 | C18: 0.5 | D18: bar | F18: K_CH4*P_CH4 | G18: =G4*C18 -> 0.58010865 | K18: K_CO*P_CO | L18: =($C10*EXP(-$C11/($C$1*L$14)))*L$29 -> 1.2434804e-08 | M18: =($C10*EXP(-$C11/($C$1*M$14)))*M$29 -> 6.5981197e-08 | N18: =($C10*EXP(-$C11/($C$1*N$14)))*N$29 -> 3.6765813e-07 | O18: =($C10*EXP(-$C11/($C$1*O$14)))*O$29 -> 1.5501155e-06 | P18: =($C10*EXP(-$C11/($C$1*P$14)))*P$29 -> 4.6615826e-06 | Q18: =($C10*EXP(-$C11/($C$1*Q$14)))*Q$29 -> 9.2385654e-06 | R18: =($C10*EXP(-$C11/($C$1*R$14)))*R$29 -> 1.205036e-05 | S18: =($C10*EXP(-$C11/($C$1*S$14)))*S$29 -> 1.2382929e-05 | ... W18: =($C10*EXP(-$C11/($C$1*W$14)))*W$29 -> 1.0988097e-05
B19: P_CO2 | C19: 0.5 | D19: bar | F19: K_CO2*P_CO2 | G19: =G6*C19 -> 0.43832433 | K19: K_H2O*P_H2O | L19: =($C8*EXP(-$C9/($C$1*L$14)))*L$30 -> 3.0654696e-07 | M19: =($C8*EXP(-$C9/($C$1*M$14)))*M$30 -> 9.8469778e-07 | N19: =($C8*EXP(-$C9/($C$1*N$14)))*N$30 -> 4.2601283e-06 | O19: =($C8*EXP(-$C9/($C$1*O$14)))*O$30 -> 1.3540194e-05 | P19: =($C8*EXP(-$C9/($C$1*P$14)))*P$30 -> 2.692367e-05 | Q19: =($C8*EXP(-$C9/($C$1*Q$14)))*Q$30 -> 2.6438011e-05 | R19: =($C8*EXP(-$C9/($C$1*R$14)))*R$30 -> 1.0838678e-05 | S19: =($C8*EXP(-$C9/($C$1*S$14)))*S$30 -> 3.5572088e-06 | ... W19: =($C8*EXP(-$C9/($C$1*W$14)))*W$30 -> 3.7332663e-07 | AF19: $7,21\cdot 10^{-5}$ | AG19: $9,93\cdot 10^{-5}$ | AH19: $1,31\cdot 10^{-4}$ | AI19: $1,57\cdot 10^{-4}$ | AJ19: $1,69\cdot 10^{-4}$ | AK19: $1,66\cdot 10^{-4}$ | AL19: $1,53\cdot 10^{-4}$ | AM19: $1,36
B20: P_H2 | C20: 0 | D20: bar | F20: sqrt(K_H2*P_H2) | G20: =SQRT(G8*C20) -> 0 | K20: Ω_total | L20: =1+SUM(L15:L19) -> 2.3300732 | M20: =1+SUM(M15:M19) -> 2.029367 | N20: =1+SUM(N15:N19) -> 1.8128879 | O20: =1+SUM(O15:O19) -> 1.6289853 | P20: =1+SUM(P15:P19) -> 1.4278121 | Q20: =1+SUM(Q15:Q19) -> 1.2084403 | R20: =1+SUM(R15:R19) -> 1.0662229 | S20: =1+SUM(S15:S19) -> 1.0266833 | ... W20: =1+SUM(W15:W19) -> 1.0104158
B21: P_CO | C21: 0 | D21: bar | F21: K_CO*P_CO | G21: =G10*C21 -> 0 | K21: (Ω_total)^2 | L21: =L20^2 -> 5.4292411 | M21: =M20^2 -> 4.1183302 | N21: =N20^2 -> 3.2865625 | O21: =O20^2 -> 2.6535931 | P21: =P20^2 -> 2.0386475 | Q21: =Q20^2 -> 1.460328 | R21: =R20^2 -> 1.1368314 | S21: =S20^2 -> 1.0540785 | ... W21: =W20^2 -> 1.0209402 | AF21: $0,658$ | AG21: $0,439$ | AH21: $0,276$ | AI21: $0,158$ | AJ21: $0,082$ | AK21: $0,040$ | AL21: $0,019$ | AM21: $9,27\cdot 10^{-3}$ | AN21: $4,92\cdot 10^{-3}$ | AO21: $2,83\cdot 10^{-3}$ | AP21: $1,95\cdot 10^{-3}$ | AQ21: $1,29\cdot 10^{-3}$
B22: P_H2O | C22: 0 | D22: bar | F22: K_H2O*P_H2O | G22: =G12*C22 -> 0 | L22: =1/L21 -> 0.18418781 | M22: =1/M21 -> 0.24281686 | N22: =1/N21 -> 0.30426928 | O22: =1/O21 -> 0.37684753 | P22: =1/P21 -> 0.49052128 | Q22: =1/Q21 -> 0.68477765 | R22: =1/R21 -> 0.87963794 | S22: =1/S21 -> 0.94869594 | ... W22: =1/W21 -> 0.97948931
B23: Outlet | F23: Ω_otherMid | G23: =1+SUM(#REF!) -> #REF! | K23: PARTIAL PRESSURES - DWSIM [bar] | AF23: $0,463$ | AG23: $0,300$ | AH23: $0,181$ | AI23: $9,70\cdot 10^{-2}$ | AJ23: $4,70\cdot 10^{-2}$ | AK23: $2,10\cdot 10^{-2}$ | AL23: $8,92\cdot 10^{-3}$ | AM23: $4,00\cdot 10^{-3}$ | AN23: $1,94\cdot 10^{-3}$ | AO23: $9,37\cdot 10^{-4}$ | AP23: $4,27\cdot 10^{-4}$ | AQ23: $1,89\cdot 10^{-4}$
B24: P_CH4 | C24: 0.2 | D24: bar | F24: K_CH4*P_CH4 | G24: =G4*C24 -> 0.23204346 | K24: Outlet
B25: P_CO2 | C25: 0.2 | D25: bar | F25: K_CO2*P_CO2 | G25: =G6*C25 -> 0.17532973 | K25: Temperature | L25: 723 | M25: 773 | N25: 823 | O25: 873 | P25: 923 | Q25: 973 | R25: 1023 | S25: 1073 | T25: 1123 | U25: 1173 | V25: 1223 | W25: 1273 | AF25: $7,21\cdot 10^{-5}$ | AG25: $9,93\cdot 10^{-5}$ | AH25: $1,31\cdot 10^{-4}$ | AI25: $1,57\cdot 10^{-4}$ | AJ25: $1,69\cdot 10^{-4}$ | AK25: $1,66\cdot 10^{-4}$ | AL25: $1,53\cdot 10^{-4}$ | AM25: $1,36
B26: P_H2 | C26: 0.4 | D26: bar | F26: sqrt(K_H2*P_H2) | G26: =SQRT(G8*C26) -> 0.02063837 | K26: P_CH4 | L26: =L33*L$38 -> 0.50646541 | M26: =M33*M$38 -> 0.50569725 | N26: =N33*N$38 -> 0.5008736 | O26: =O33*O$38 -> 0.47842488 | P26: =P33*P$38 -> 0.4009036 | Q26: =Q33*Q$38 -> 0.2370043 | R26: =R33*R$38 -> 0.080047739 | S26: =S33*S$38 -> 0.026166042 | ... W26: =W33*W$38 -> 0.0034331635
B27: P_CO | C27: 0.4 | D27: bar | F27: K_CO*P_CO | G27: =G10*C27 -> 1.4372677e-05 | K27: P_CO2 | L27: =L34*L$38 -> 0.50625833 | M27: =M34*M$38 -> 0.50477388 | N27: =N34*N$38 -> 0.49556248 | O27: =O34*O$38 -> 0.45672143 | P27: =P34*P$38 -> 0.34691576 | Q27: =Q34*Q$38 -> 0.17219452 | R27: =R34*R$38 -> 0.048198241 | S27: =S34*S$38 -> 0.013846249 | ... W27: =W34*W$38 -> 0.0012407248
B28: P_H2O | C28: 0.05 | D28: bar | F28: K_H2O*P_H2O | G28: =G12*C28 -> 0.0021776877 | K28: P_H2 | L28: =L35*L$38 -> 1.0307966e-06 | M28: =M35*M$38 -> 1.7847841e-05 | N28: =N35*N$38 -> 0.00044250855 | O28: =O35*O$38 -> 0.006496906 | P28: =P35*P$38 -> 0.051732967 | Q28: =Q35*Q$38 -> 0.20481041 | R28: =R35*R$38 -> 0.39472736 | S28: =S35*S$38 -> 0.46813881 | ... W28: =W35*W$38 -> 0.50099905
F29: Ω_outlet | G29: =1+SUM(G24:G28) -> 1.4302036 | K29: P_CO | L29: =L36*L$38 -> 0.00031677179 | M29: =M36*M$38 -> 0.0018362952 | N29: =N36*N$38 -> 0.011058943 | O29: =O36*O$38 -> 0.049947642 | P29: =P36*P$38 -> 0.15970862 | Q29: =Q36*Q$38 -> 0.33442998 | R29: =R36*R$38 -> 0.45842637 | S29: =S36*S$38 -> 0.49277839 | ... W29: =W36*W$38 -> 0.50538393
K30: P_H2O | L30: =L37*L$38 -> 0.0002084521 | M30: =M37*M$38 -> 0.00092472404 | N30: =N37*N$38 -> 0.0053124709 | O30: =O37*O$38 -> 0.021704774 | P30: =P37*P$38 -> 0.053989047 | Q30: =Q37*Q$38 -> 0.064810784 | R30: =R37*R$38 -> 0.031850287 | S30: =S37*S$38 -> 0.012320509 | ... W30: =W37*W$38 -> 0.0021931241
K31: PARTIAL PRESSURES - DWSIM [Pa]
K32: Temperature | L32: 723 | M32: 773 | N32: 823 | O32: 873 | P32: 923 | Q32: 973 | R32: 1023 | S32: 1073 | T32: 1123 | U32: 1173 | V32: 1223 | W32: 1273
K33: y_CH4 | L33: 0.4998425 | M33: 0.49908438 | N33: 0.49432381 | O33: 0.47216865 | P33: 0.39566109 | Q33: 0.23390506 | R33: 0.079000976 | S33: 0.025823876 | T33: 0.014477195 | U33: 0.0086072121 | V33: 0.0053055479 | W33: 0.0033882689
K34: y_CO2 | L34: 0.49963812 | M34: 0.49817309 | N34: 0.48908214 | O34: 0.45074901 | P34: 0.34237924 | Q34: 0.16994278 | R34: 0.047567965 | S34: 0.013665185 | T34: 0.0069289029 | U34: 0.0037392018 | V34: 0.0020987883 | W34: 0.0012245002
K35: y_H2 | L35: 1.0173171e-06 | M35: 1.761445e-05 | N35: 0.00043672198 | O35: 0.0064119477 | P35: 0.051056469 | Q35: 0.20213216 | R35: 0.38956562 | S35: 0.46201708 | T35: 0.47797417 | U35: 0.48652444 | V35: 0.49148735 | W35: 0.49444762
K36: y_CO | L36: 0.00031262945 | M36: 0.0018122825 | N36: 0.010914328 | O36: 0.04929449 | P36: 0.15762015 | Q36: 0.33005673 | R36: 0.45243165 | S36: 0.48633446 | T36: 0.49307075 | U36: 0.49626046 | V36: 0.49790087 | W36: 0.49877516
K37: y_H2O | L37: 0.00020572623 | M37: 0.00091263167 | N37: 0.0052430011 | O37: 0.021420946 | P37: 0.053283047 | Q37: 0.063963271 | R37: 0.031433789 | S37: 0.012159397 | T37: 0.0075489837 | U37: 0.0048686939 | V37: 0.0032074387 | W37: 0.0021644452
K38: Stream pressure | L38: 1.01325 | M38: 1.01325 | N38: 1.01325 | O38: 1.01325 | P38: 1.01325 | Q38: 1.01325 | R38: 1.01325 | S38: 1.01325 | T38: 1.01325 | U38: 1.01325 | V38: 1.01325 | W38: 1.01325
G40: K_2 = K_CO2 | H40: 0.0261 | K40: K_CO2*P_CO2 | L40: 0.46321883 | M40: 0.30041473 | N40: 0.18081757 | O40: 0.097268475 | P40: 0.04657577 | Q40: 0.020573156 | R40: 0.0089159601 | S40: 0.0040012034 | T40: 0.001944073 | U40: 0.00093694962 | V40: 0.00042742317 | W40: 0.00018877169
G41: dH_2=dH_CO2 | H41: -37641 | K41: Ω_total | L41: 2.1211388 | M41: 1.7391214 | N41: 1.4568419 | O41: 1.255559 | P41: 1.1287718 | Q41: 1.0603713 | R41: 1.0279123 | S41: 1.013408 | T41: 1.0069914 | U41: 1.0038763 | V41: 1.0024707 | W41: 1.0015669
...

Sheet Carbón Bulk
B1: R= | C1: 8.314 | D1: J/mol K
B2: T= | C2: 723 | D2: K
A3: CARBON DISSOLUTION INTO DE BULK METAL PHASE
A4: Parameter | B4: Min | C4: Central | D4: Max | E4: Limite | F4: Units
A5: D_C | B5: 5e-10 | C5: 1e-09 | D5: 5e-08 | F5: m2/s | G5: Outlet
A6: s | B6: ='Surface Renewal'!B5 -> 30 | C6: 50 | D6: ='Surface Renewal'!C5 -> 80 | E6: 0.1 | G6: Temperature | H6: 723 | I6: 773 | J6: 823 | K6: 873 | L6: 923 | M6: 973 | N6: 1023 | O6: 1073 | P6: 1123 | Q6: 1173 | R6: 1223 | S6: 1273
A7: δ | B7: =SQRT(D5/D6) -> 2.5e-05 | C7: =SQRT(C5/C6) -> 4.472136e-06 | D7: =SQRT(B5/B6) -> 4.0824829e-06 | E7: =SQRT(C5/E6) -> 0.0001 | F7: m2/s | G7: P_CH4 | H7: ='Ads equilibria Ω'!L26 -> 0.50646541 | I7: ='Ads equilibria Ω'!M26 -> 0.50569725 | J7: ='Ads equilibria Ω'!N26 -> 0.5008736 | K7: ='Ads equilibria Ω'!O26 -> 0.47842488 | L7: ='Ads equilibria Ω'!P26 -> 0.4009036 | M7: ='Ads equilibria Ω'!Q26 -> 0.2370043 | N7: ='Ads equilibria Ω'!R26 -> 0.080047739 | O7: ='Ads equilibria Ω'!S26 -> 0.026166042 | ... S7: ='Ads equilibria Ω'!W26 -> 0.0034331635
B8: =SQRT(D5/B6) -> 4.0824829e-05 | C8: =SQRT(C5/D6) -> 3.5355339e-06 | D8: =SQRT(B5/D6) -> 2.5e-06 | E8: =SQRT(D5/E6) -> 0.00070710678 | G8: P_CO2 | H8: ='Ads equilibria Ω'!L27 -> 0.50625833 | I8: ='Ads equilibria Ω'!M27 -> 0.50477388 | J8: ='Ads equilibria Ω'!N27 -> 0.49556248 | K8: ='Ads equilibria Ω'!O27 -> 0.45672143 | L8: ='Ads equilibria Ω'!P27 -> 0.34691576 | M8: ='Ads equilibria Ω'!Q27 -> 0.17219452 | N8: ='Ads equilibria Ω'!R27 -> 0.048198241 | O8: ='Ads equilibria Ω'!S27 -> 0.013846249 | ... S8: ='Ads equilibria Ω'!W27 -> 0.0012407248
A9: a_s | B9: 200 | C9: 200 | D9: 200 | F9: m2/m3 | G9: P_H2 | H9: ='Ads equilibria Ω'!L28 -> 1.0307966e-06 | I9: ='Ads equilibria Ω'!M28 -> 1.7847841e-05 | J9: ='Ads equilibria Ω'!N28 -> 0.00044250855 | K9: ='Ads equilibria Ω'!O28 -> 0.006496906 | L9: ='Ads equilibria Ω'!P28 -> 0.051732967 | M9: ='Ads equilibria Ω'!Q28 -> 0.20481041 | N9: ='Ads equilibria Ω'!R28 -> 0.39472736 | O9: ='Ads equilibria Ω'!S28 -> 0.46813881 | ... S9: ='Ads equilibria Ω'!W28 -> 0.50099905
A10: Dens_cat | B10: ='Mass Transfer '!B10 -> 250 | C10: ='Mass Transfer '!C10 -> 6400 | D10: ='Mass Transfer '!C10 -> 6400 | F10: kg/m3 | G10: P_CO | H10: ='Ads equilibria Ω'!L29 -> 0.00031677179 | I10: ='Ads equilibria Ω'!M29 -> 0.0018362952 | J10: ='Ads equilibria Ω'!N29 -> 0.011058943 | K10: ='Ads equilibria Ω'!O29 -> 0.049947642 | L10: ='Ads equilibria Ω'!P29 -> 0.15970862 | M10: ='Ads equilibria Ω'!Q29 -> 0.33442998 | N10: ='Ads equilibria Ω'!R29 -> 0.45842637 | O10: ='Ads equilibria Ω'!S29 -> 0.49277839 | ... S10: ='Ads equilibria Ω'!W29 -> 0.50538393
A11: C_sat | B11: 5 | C11: 20 | D11: 50 | F11: mol/m3 | G11: P_H2O | H11: ='Ads equilibria Ω'!L30 -> 0.0002084521 | I11: ='Ads equilibria Ω'!M30 -> 0.00092472404 | J11: ='Ads equilibria Ω'!N30 -> 0.0053124709 | K11: ='Ads equilibria Ω'!O30 -> 0.021704774 | L11: ='Ads equilibria Ω'!P30 -> 0.053989047 | M11: ='Ads equilibria Ω'!Q30 -> 0.064810784 | N11: ='Ads equilibria Ω'!R30 -> 0.031850287 | O11: ='Ads equilibria Ω'!S30 -> 0.012320509 | ... S11: ='Ads equilibria Ω'!W30 -> 0.0021931241
G12: (Ω_total)^2 | H12: ='Ads equilibria Ω'!L21 -> 5.4292411 | I12: ='Ads equilibria Ω'!M21 -> 4.1183302 | J12: ='Ads equilibria Ω'!N21 -> 3.2865625 | K12: ='Ads equilibria Ω'!O21 -> 2.6535931 | L12: ='Ads equilibria Ω'!P21 -> 2.0386475 | M12: ='Ads equilibria Ω'!Q21 -> 1.460328 | N12: ='Ads equilibria Ω'!R21 -> 1.1368314 | O12: ='Ads equilibria Ω'!S21 -> 1.0540785 | ... S12: ='Ads equilibria Ω'!W21 -> 1.0209402
A13: k_diss
B14: =(B$5/B7)*B$11*(B$9/C$10) -> 3.125e-06 | C14: =(C$5/C7)*C$11*(C$9/C$10) -> 0.00013975425 | D14: =(D$5/D7)*D$11*(D$9/D$10) -> 0.019136639 | E14: =(B$5/E7)*B$11*(D$9/D$10) -> 7.8125e-07 | F14: =(B$5/E8)*B$11*(D$9/D$10) -> 1.1048543e-07
B15: =(B$5/B8)*B$11*(B$9/C$10) -> 1.9136639e-06 | C15: =(C$5/C8)*C$11*(C$9/C$10) -> 0.0001767767 | D15: =(D$5/D8)*D$11*(D$9/D$10) -> 0.03125 | E15: =(D$5/D8)*D$11*(D$9/D$10) -> 0.03125
A17: r_crack | G17: Temp. | H17: 723 | I17: 773 | J17: 823 | K17: 873 | L17: 923 | M17: 973 | N17: 1023 | O17: 1073 | P17: 1123 | Q17: 1173 | R17: 1223 | S17: 1273
B18: A_crack | C18: ='Domain-Shift'!L30 -> 6950 | D18: mol/m3·s | G18: k_crack | H18: =$C$18*EXP(-$C$19/(H17*$C$1)) -> 5.3700995e-08 | I18: =$C$18*EXP(-$C$19/(I17*$C$1)) -> 2.8102217e-07 | J18: =$C$18*EXP(-$C$19/(J17*$C$1)) -> 1.202721e-06 | K18: =$C$18*EXP(-$C$19/(K17*$C$1)) -> 4.3577379e-06 | L18: =$C$18*EXP(-$C$19/(L17*$C$1)) -> 1.3733572e-05 | M18: =$C$18*EXP(-$C$19/(M17*$C$1)) -> 3.8465407e-05 | N18: =$C$18*EXP(-$C$19/(N17*$C$1)) -> 9.7416851e-05 | O18: =$C$18*EXP(-$C$19/(O17*$C$1)) -> 0.0002262492 | ... S18: =$C$18*EXP(-$C$19/(S17*$C$1)) -> 0.0033956745
B19: Ea_crack | C19: ='Domain-Shift'!L31 -> 153800 | D19: J/mol | G19: K_eq,crack | H19: =($C$20*EXP(-$C$21/(H17*$C$1))) -> 0.23629382 | I19: =($C$20*EXP(-$C$21/(I17*$C$1))) -> 0.58623048 | J19: =($C$20*EXP(-$C$21/(J17*$C$1))) -> 1.3023747 | K19: =($C$20*EXP(-$C$21/(K17*$C$1))) -> 2.640545 | L19: =($C$20*EXP(-$C$21/(L17*$C$1))) -> 4.9590068 | M19: =($C$20*EXP(-$C$21/(M17*$C$1))) -> 8.7290345 | N19: =($C$20*EXP(-$C$21/(N17*$C$1))) -> 14.538938 | O19: =($C$20*EXP(-$C$21/(O17*$C$1))) -> 23.091381 | ... S19: =($C$20*EXP(-$C$21/(S17*$C$1))) -> 102.16193
B20: K_crack | C20: ='Domain-Shift'!L40 -> 298000 | G20: K1=K_CH4 | H20: ='Domain-Shift'!U11 -> 1.5087497 | I20: ='Domain-Shift'!V11 -> 1.1602173 | J20: ='Domain-Shift'!W11 -> 0.92113374 | K20: ='Domain-Shift'!X11 -> 0.75090607 | L20: ='Domain-Shift'!Y11 -> 0.62583885 | M20: ='Domain-Shift'!Z11 -> 0.53146088 | N20: ='Domain-Shift'!AA11 -> 0.45858473 | O20: ='Domain-Shift'!AB11 -> 0.40117817 | ... S20: ='Domain-Shift'!AF11 -> 0.26099632
B21: dH_crack | C21: ='Domain-Shift'!L41 -> 84440 | G21: r_crack | H21: =(H$18*H$20*H$7*(1-(H$9^2/(H$19*H$7))))/H$12 -> 7.5580577e-09 | I21: =(I$18*I$20*I$7*(1-(I$9^2/(I$19*I$7))))/I$12 -> 4.0035876e-08 | J21: =(J$18*J$20*J$7*(1-(J$9^2/(J$19*J$7))))/J$12 -> 1.6883936e-07 | K21: =(K$18*K$20*K$7*(1-(K$9^2/(K$19*K$7))))/K$12 -> 5.8994517e-07 | L21: =(L$18*L$20*L$7*(1-(L$9^2/(L$19*L$7))))/L$12 -> 1.6879471e-06 | M21: =(M$18*M$20*M$7*(1-(M$9^2/(M$19*M$7))))/M$12 -> 3.2505077e-06 | N21: =(N$18*N$20*N$7*(1-(N$9^2/(N$19*N$7))))/N$12 -> 2.7244901e-06 | O21: =(O$18*O$20*O$7*(1-(O$9^2/(O$19*O$7))))/O$12 -> 1.4359043e-06 | ... S21: =(S$18*S$20*S$7*(1-(S$9^2/(S$19*S$7))))/S$12 -> 8.4748909e-07
A22: r_Boud | G22: Temp. | H22: 723 | I22: 773 | J22: 823 | K22: 873 | L22: 923 | M22: 973 | N22: 1023 | O22: 1073 | P22: 1123 | Q22: 1173 | R22: 1223 | S22: 1273
B23: A_Boud | C23: ='Domain-Shift'!L32 -> 1.34e+15 | D23: mol/m3·s | G23: k_Boud | H23: =$C$23*EXP(-$C$24/(H22*$C$1)) -> 9.4622042e-18 | I23: =$C$23*EXP(-$C$24/(I22*$C$1)) -> 1.1366439e-15 | J23: =$C$23*EXP(-$C$24/(J22*$C$1)) -> 7.6307521e-14 | K23: =$C$23*EXP(-$C$24/(K22*$C$1)) -> 3.1640144e-12 | L23: =$C$23*EXP(-$C$24/(L22*$C$1)) -> 8.7628876e-11 | M23: =$C$23*EXP(-$C$24/(M22*$C$1)) -> 1.7250933e-09 | N23: =$C$23*EXP(-$C$24/(N22*$C$1)) -> 2.5378798e-08 | O23: =$C$23*EXP(-$C$24/(O22*$C$1)) -> 2.9060807e-07 | ... S23: =$C$23*EXP(-$C$24/(S22*$C$1)) -> 0.00073601947
B24: Ea_Boud | C24: ='Domain-Shift'!L33 -> 445000 | D24: J/mol | G24: K_eq,Boud | H24: =1/(($C$25*EXP(-$C$26/(H22*$C$1)))) -> 777.08113 | I24: =1/(($C$25*EXP(-$C$26/(I22*$C$1)))) -> 126.73133 | J24: =1/(($C$25*EXP(-$C$26/(J22*$C$1)))) -> 25.7631 | K24: =1/(($C$25*EXP(-$C$26/(K22*$C$1)))) -> 6.2858798 | L24: =1/(($C$25*EXP(-$C$26/(L22*$C$1)))) -> 1.786932 | M24: =1/(($C$25*EXP(-$C$26/(M22*$C$1)))) -> 0.5780849 | N24: =1/(($C$25*EXP(-$C$26/(N22*$C$1)))) -> 0.20882617 | O24: =1/(($C$25*EXP(-$C$26/(O22*$C$1)))) -> 0.08294504 | ... S24: =1/(($C$25*EXP(-$C$26/(S22*$C$1)))) -> 0.0042639489
B25: K_Boud | C25: ='Domain-Shift'!L42 -> 1930000000 | G25: K_-21=K_CO | H25: ='Domain-Shift'!U14 -> 3.9254772e-05 | I25: ='Domain-Shift'!V14 -> 3.5931693e-05 | J25: ='Domain-Shift'!W14 -> 3.3245323e-05 | K25: ='Domain-Shift'!X14 -> 3.1034809e-05 | L25: ='Domain-Shift'!Y14 -> 2.9188047e-05 | M25: ='Domain-Shift'!Z14 -> 2.7624812e-05 | N25: ='Domain-Shift'!AA14 -> 2.628636e-05 | O25: ='Domain-Shift'!AB14 -> 2.5128798e-05 | ... S25: ='Domain-Shift'!AF14 -> 2.1742078e-05
B26: dH_Boud | C26: ='Domain-Shift'!L43 -> 168527 | G26: r_Boud | H26: =(H$23*H$10*H$25*(1-(H$8/(H$24*H$10*H$10))))/H$12 -> -1.4068185e-22 | I26: =(I$23*I$10*I$25*(1-(I$8/(I$24*I$10*I$10))))/I$12 -> -2.1492331e-20 | J26: =(J$23*J$10*J$25*(1-(J$8/(J$24*J$10*J$10))))/J$12 -> -1.3340515e-18 | K26: =(K$23*K$10*K$25*(1-(K$8/(K$24*K$10*K$10))))/K$12 -> -5.1981614e-17 | L26: =(L$23*L$10*L$25*(1-(L$8/(L$24*L$10*L$10))))/L$12 -> -1.3247255e-15 | M26: =(M$23*M$10*M$25*(1-(M$8/(M$24*M$10*M$10))))/M$12 -> -1.8152348e-14 | N26: =(N$23*N$10*N$25*(1-(N$8/(N$24*N$10*N$10))))/N$12 -> -2.6434621e-14 | O26: =(O$23*O$10*O$25*(1-(O$8/(O$24*O$10*O$10))))/O$12 -> 1.067047e-12 | ... S26: =(S$23*S$10*S$25*(1-(S$8/(S$24*S$10*S$10))))/S$12 -> -1.1031123e-09
A27: r_gass, H2O | G27: Temp. | H27: 723 | I27: 773 | J27: 823 | K27: 873 | L27: 923 | M27: 973 | N27: 1023 | O27: 1073 | P27: 1123 | Q27: 1173 | R27: 1223 | S27: 1273
B28: A_gas | C28: ='Domain-Shift'!L34 -> 5550000000 | D28: mol/m3·s | G28: k_gas,H2O | H28: =$C$28*EXP(-$C$29/(H27*$C$1)) -> 0.0052742554 | I28: =$C$28*EXP(-$C$29/(I27*$C$1)) -> 0.031607442 | J28: =$C$28*EXP(-$C$29/(J27*$C$1)) -> 0.15238089 | K28: =$C$28*EXP(-$C$29/(K27*$C$1)) -> 0.61350703 | L28: =$C$28*EXP(-$C$29/(L27*$C$1)) -> 2.1240927 | M28: =$C$28*EXP(-$C$29/(M27*$C$1)) -> 6.4728469 | N28: =$C$28*EXP(-$C$29/(N27*$C$1)) -> 17.689396 | O28: =$C$28*EXP(-$C$29/(O27*$C$1)) -> 44.01892 | ... S28: =$C$28*EXP(-$C$29/(S27*$C$1)) -> 824.75796
B29: Ea_gas | C29: ='Domain-Shift'!L35 -> 166397 | D29: J/mol | G29: K_gas,H2O | H29: =$C$30*EXP(-$C$31/(H27*$C$1)) -> 0.011049328 | I29: =$C$30*EXP(-$C$31/(I27*$C$1)) -> 0.042833442 | J29: =$C$30*EXP(-$C$31/(J27*$C$1)) -> 0.14084123 | K29: =$C$30*EXP(-$C$31/(K27*$C$1)) -> 0.4040747 | L29: =$C$30*EXP(-$C$31/(L27*$C$1)) -> 1.0341934 | M29: =$C$30*EXP(-$C$31/(M27*$C$1)) -> 2.4032298 | N29: =$C$30*EXP(-$C$31/(N27*$C$1)) -> 5.142719 | O29: =$C$30*EXP(-$C$31/(O27*$C$1)) -> 10.251758 | ... S29: =$C$30*EXP(-$C$31/(S27*$C$1)) -> 94.160039
B30: K_gas | C30: ='Domain-Shift'!L44 -> 13827000 | G30: K-23=K_H2O | H30: ='Domain-Shift'!U15 -> 0.081878997 | I30: ='Domain-Shift'!V15 -> 0.043553754 | J30: ='Domain-Shift'!W15 -> 0.025014358 | K30: ='Domain-Shift'!X15 -> 0.015308771 | L30: ='Domain-Shift'!Y15 -> 0.00988087 | M30: ='Domain-Shift'!Z15 -> 0.0066710194 | N30: ='Domain-Shift'!AA15 -> 0.0046802166 | O30: ='Domain-Shift'!AB15 -> 0.0033937911 | ... S30: ='Domain-Shift'!AF15 -> 0.0012078386
B31: dH_gas | C31: ='Domain-Shift'!L45 -> 125916 | G31: r_gas,H2O | H31: =(H$28*H$30*H$11*(1-((H$10*H$9)/(H$29*H$11))))/H$12 -> 1.6578272e-08 | I31: =(I$28*I$30*I$11*(1-((I$10*I$9)/(I$29*I$11))))/I$12 -> 3.0884916e-07 | J31: =(J$28*J$30*J$11*(1-((J$10*J$9)/(J$29*J$11))))/J$12 -> 6.121033e-06 | K31: =(K$28*K$30*K$11*(1-((K$10*K$9)/(K$29*K$11))))/K$12 -> 7.3978747e-05 | L31: =(L$28*L$30*L$11*(1-((L$10*L$9)/(L$29*L$11))))/L$12 -> 0.00047357037 | M31: =(M$28*M$30*M$11*(1-((M$10*M$9)/(M$29*M$11))))/M$12 -> 0.0010736416 | N31: =(N$28*N$30*N$11*(1-((N$10*N$9)/(N$29*N$11))))/N$12 -> -0.00024294907 | O31: =(O$28*O$30*O$11*(1-((O$10*O$9)/(O$29*O$11))))/O$12 -> -0.0014430388 | ... S31: =(S$28*S$30*S$11*(1-((S$10*S$9)/(S$29*S$11))))/S$12 -> -0.00048385255
A32: r_accum,surf | G32: Temp.
G33: Max.
C34: 1e-06 | G34: Central
C35: =C34/D15 -> 3.2e-05 | G35: Min.
A40: θ_C^SS | G40: Temp. | H40: 723 | I40: 773 | J40: 823 | K40: 873 | L40: 923 | M40: 973 | N40: 1023 | O40: 1073 | P40: 1123 | Q40: 1173 | R40: 1223 | S40: 1273
A41: T=0 | B41: C_bulk =0 | C41: max k_diss | G41: θ_C^SS | H41: =(H$21+H$26)/($D$15*(1-$B$42/$C$11)) -> 2.4185785e-07 | I41: =(I$21+I$26)/($D$15*(1-$B$42/$C$11)) -> 1.281148e-06 | J41: =(J$21+J$26)/($D$15*(1-$B$42/$C$11)) -> 5.4028596e-06 | K41: =(K$21+K$26)/($D$15*(1-$B$42/$C$11)) -> 1.8878245e-05 | L41: =(L$21+L$26)/($D$15*(1-$B$42/$C$11)) -> 5.4014306e-05 | M41: =(M$21+M$26)/($D$15*(1-$B$42/$C$11)) -> 0.00010401624 | N41: =(N$21+N$26)/($D$15*(1-$B$42/$C$11)) -> 8.7183681e-05 | O41: =(O$21+O$26)/($D$15*(1-$B$42/$C$11)) -> 4.5948972e-05 | ... S41: =(S$21+S$26)/($D$15*(1-$B$42/$C$11)) -> 2.7084351e-05
B42: 0 | C42: media k_diss | G42: θ_C^SS | H42: =(H$21+H$26)/($C$14*(1-$B$42/$C$11)) -> 5.4081059e-05 | I42: =(I$21+I$26)/($C$14*(1-$B$42/$C$11)) -> 0.00028647341 | J42: =(J$21+J$26)/($C$14*(1-$B$42/$C$11)) -> 0.0012081161 | K42: =(K$21+K$26)/($C$14*(1-$B$42/$C$11)) -> 0.004221304 | L42: =(L$21+L$26)/($C$14*(1-$B$42/$C$11)) -> 0.012077966 | M42: =(M$21+M$26)/($C$14*(1-$B$42/$C$11)) -> 0.023258739 | N42: =(N$21+N$26)/($C$14*(1-$B$42/$C$11)) -> 0.019494864 | O42: =(O$21+O$26)/($C$14*(1-$B$42/$C$11)) -> 0.010274502 | ... S42: =(S$21+S$26)/($C$14*(1-$B$42/$C$11)) -> 0.0060562451
C43: min k_diss | G43: θ_C^SS | H43: =(H$21+H$26)/($F$14*(1-$B$42/$B$11)) -> 0.06840773 | I43: =(I$21+I$26)/($F$14*(1-$B$42/$B$11)) -> 0.36236338 | J43: =(J$21+J$26)/($F$14*(1-$B$42/$B$11)) -> 1.5281595 | K43: =(K$21+K$26)/($F$14*(1-$B$42/$B$11)) -> 5.3395741 | L43: =(L$21+L$26)/($F$14*(1-$B$42/$B$11)) -> 15.277553 | M43: =(M$21+M$26)/($F$14*(1-$B$42/$B$11)) -> 29.420237 | N43: =(N$21+N$26)/($F$14*(1-$B$42/$B$11)) -> 24.659269 | O43: =(O$21+O$26)/($F$14*(1-$B$42/$B$11)) -> 12.996332 | ... S43: =(S$21+S$26)/($F$14*(1-$B$42/$B$11)) -> 7.6606114
A44: final | B44: C_bulk \sim Csat | C44: max k_diss | G44: θ_C^SS | H44: =(H$21+H$26-H$31)/($D$15*(1-$B$45/$C$11)) -> -0.0057729368 | I44: =(I$21+I$26-I$31)/($D$15*(1-$B$45/$C$11)) -> -0.1720405 | J44: =(J$21+J$26-J$31)/($D$15*(1-$B$45/$C$11)) -> -3.8094039 | K44: =(K$21+K$26-K$31)/($D$15*(1-$B$45/$C$11)) -> -46.968833 | L44: =(L$21+L$26-L$31)/($D$15*(1-$B$45/$C$11)) -> -302.00475 | M44: =(M$21+M$26-M$31)/($D$15*(1-$B$45/$C$11)) -> -685.05032 | N44: =(N$21+N$26-N$31)/($D$15*(1-$B$45/$C$11)) -> 157.23108 | O44: =(O$21+O$26-O$31)/($D$15*(1-$B$45/$C$11)) -> 924.46384 | ... S44: =(S$21+S$26-S$31)/($D$15*(1-$B$45/$C$11)) -> 310.20732
B45: 19.999 | C45: media k_diss | G45: θ_C^SS | H45: =(H$21+H$26-H$31)/($B$14*(1-$B$45/$C$11)) -> -57.729368 | I45: =(I$21+I$26-I$31)/($B$14*(1-$B$45/$C$11)) -> -1720.405 | J45: =(J$21+J$26-J$31)/($B$14*(1-$B$45/$C$11)) -> -38094.039 | K45: =(K$21+K$26-K$31)/($B$14*(1-$B$45/$C$11)) -> -469688.33 | L45: =(L$21+L$26-L$31)/($B$14*(1-$B$45/$C$11)) -> -3020047.5 | M45: =(M$21+M$26-M$31)/($B$14*(1-$B$45/$C$11)) -> -6850503.2 | N45: =(N$21+N$26-N$31)/($B$14*(1-$B$45/$C$11)) -> 1572310.8 | O45: =(O$21+O$26-O$31)/($B$14*(1-$B$45/$C$11)) -> 9244638.4 | ... S45: =(S$21+S$26-S$31)/($B$14*(1-$B$45/$C$11)) -> 3102073.2
...

Sheet Thermo
A1: JANAF/NIST | B1: H (298K) | C1: S (298K) | D1: Cp (298K) | F1: Species | G1: Range (K) | H1: A | I1: B | J1: C | K1: D | L1: E | M1: F | N1: G | O1: H_ref (kJ/mol) | P1: S°₂₉₈ (J/mol/K) | R1: ChatGPT
A2: CH4 | B2: -74.873 | C2: 186.251 | D2: 35.639 | F2: CH₄ | G2: 298–1300 | H2: -0.703029 | I2: 108.4773 | J2: -42.52157 | K2: 5.862788 | L2: 0.678565 | M2: -76.84376 | N2: 158.7163 | O2: -74.8731 | P2: 186.251 | R2: Species | S2: Range (K) | T2: A | U2: B | V2: C | W2: D | X2: E | Y2: F | Z2: G | AA2: H_ref (kJ/mol)
A3: CO2 | B3: -393.522 | C3: 213.795 | D3: 37.129 | F3: CO₂ | G3: 298–1200 | H3: 24.99735 | I3: 55.18696 | J3: -33.69137 | K3: 7.948387 | L3: -0.136638 | M3: -403.6075 | N3: 228.2431 | O3: -393.5224 | P3: 213.785 | R3: C (gr,) | S3: 298-1100 | T3: 0.11 | U3: 38.94 | V3: -17.38 | W3: 0 | X3: -0.148 | Y3: -2.106 | Z3: -5.796 | AA3: 0
A4: H2 | B4: 0 | C4: 130.68 | D4: 28.836 | F4: CO₂ | G4: 1200–6000 | H4: 58.16639 | I4: 2.720074 | J4: -0.492289 | K4: 0.038844 | L4: -6.447293 | M4: -425.9186 | N4: 263.6125 | O4: -393.5224 | P4: — | R4: C (gr,) | S4: 1100-4000 | T4: 24.43 | U4: 0.44 | V4: 0 | W4: 0 | X4: -0.3163 | Y4: -11.331 | Z4: 29.447 | AA4: 0
A5: CO | B5: -110.527 | C5: 197.653 | D5: 29.142 | F5: CO | G5: 298–1300 | H5: 25.56759 | I5: 6.09613 | J5: 4.054656 | K5: -2.671301 | L5: 0.131021 | M5: -118.0089 | N5: 227.3665 | O5: -110.5271 | P5: 197.66 | R5: CLAUDE
A6: H2O | B6: -241.826 | C6: 188.834 | D6: 33.59 | F6: H₂ | G6: 298–1000 | H6: 33.066178 | I6: -11.363417 | J6: 11.432816 | K6: -2.772874 | L6: -0.158558 | M6: -9.980797 | N6: 172.70797 | O6: 0 | P6: 130.68 | R6: Species | S6: Range (K) | T6: A | U6: B | V6: C | W6: D | X6: E | Y6: F | Z6: G | AA6: H_ref (kJ/mol)
A7: C | B7: 0 | C7: 5.74 | D7: 8.52 | F7: H₂ | G7: 1000–2500 | H7: 18.563083 | I7: 12.257357 | J7: -2.859786 | K7: 0.268238 | L7: 1.97799 | M7: -1.147438 | N7: 156.28813 | O7: 0 | P7: — | R7: C (gr,) | S7: 298-1200 | T7: 0.49042 | U7: 10.36199 | V7: -4.170727 | W7: 0.66675 | X7: 0.60061 | Y7: -0.028056 | Z7: 2.85935 | AA7: 0
F8: H₂O | G8: 500–1700 | H8: 30.092 | I8: 6.832514 | J8: 6.793435 | K8: -2.53448 | L8: 0.082139 | M8: -250.881 | N8: 223.3967 | O8: -241.8264 | P8: 188.835 | R8: C (gr,) | S8: 1200-6000 | T8: 17.8539 | U8: 1.497698 | V8: -0.182476 | W8: 0.008501 | X8: -1.297698 | Y8: -8.66374 | Z8: 26.72484 | AA8: 0
A9: R= | B9: 8.314 | C9: J/mol K | F9: C (gr,) | G9: 298–1200
A10: K4 = K_DRM | B10: ='Domain-Shift'!L22 -> 678000000000000
A11: dH_4 = dH_DRM | B11: ='Domain-Shift'!L23 -> 259660 | G11: T | H11: 700 | I11: 800 | J11: 900 | K11: 1000 | L11: 1073 | M11: 1100 | N11: 1200 | O11: 1273 | P11: 1300
A12: K_11 = K_RWGS | B12: ='Domain-Shift'!L24 -> 56.4971 | G12: t | H12: =H11/1000 -> 0.7 | I12: =I11/1000 -> 0.8 | J12: =J11/1000 -> 0.9 | K12: =K11/1000 -> 1 | L12: =L11/1000 -> 1.073 | M12: =M11/1000 -> 1.1 | N12: =N11/1000 -> 1.2 | O12: =O11/1000 -> 1.273 | P12: =P11/1000 -> 1.3
A13: dH_11 = dH_RWGS | B13: ='Domain-Shift'!L25 -> 36580 | F13: CH4 | G13: H (K)-H(298) | H13: =($H$2*H$12)+(($I$2*H$12^2)/2)+(($J$2*H$12^3)/3)+(($K$2*H$12^4)/4)-($L$2/H$12)+$M$2-$O$2 -> 18.635061 | I13: =($H$2*I$12)+(($I$2*I$12^2)/2)+(($J$2*I$12^3)/3)+(($K$2*I$12^4)/4)-($L$2/I$12)+$M$2-$O$2 -> 24.674781 | J13: =($H$2*J$12)+(($I$2*J$12^2)/2)+(($J$2*J$12^3)/3)+(($K$2*J$12^4)/4)-($L$2/J$12)+$M$2-$O$2 -> 31.204862 | K13: =($H$2*K$12)+(($I$2*K$12^2)/2)+(($J$2*K$12^3)/3)+(($K$2*K$12^4)/4)-($L$2/K$12)+$M$2-$O$2 -> 38.178236 | L13: =($H$2*L$12)+(($I$2*L$12^2)/2)+(($J$2*L$12^3)/3)+(($K$2*L$12^4)/4)-($L$2/L$12)+$M$2-$O$2 -> 43.521945 | M13: =($H$2*M$12)+(($I$2*M$12^2)/2)+(($J$2*M$12^3)/3)+(($K$2*M$12^4)/4)-($L$2/M$12)+$M$2-$O$2 -> 45.548421 | N13: =($H$2*N$12)+(($I$2*N$12^2)/2)+(($J$2*N$12^3)/3)+(($K$2*N$12^4)/4)-($L$2/N$12)+$M$2-$O$2 -> 53.270735 | O13: =($H$2*O$12)+(($I$2*O$12^2)/2)+(($J$2*O$12^3)/3)+(($K$2*O$12^4)/4)-($L$2/O$12)+$M$2-$O$2 -> 59.106011 | P13: =($H$2*P$12)+(($I$2*P$12^2)/2)+(($J$2*P$12^3)/3)+(($K$2*P$12^4)/4)-($L$2/P$12)+$M$2-$O$2 -> 61.302962
A14: K_crack | B14: 298000 | G14: S (K) | H14: =($H$2*LN(H$12))+($I$2*H$12)+(($J$2*H$12^2)/2)+(($K$2*H$12^3)/3)-($L$2/(2*H$12^2))+$N$2 -> 224.46128 | I14: =($H$2*LN(I$12))+($I$2*I$12)+(($J$2*I$12^2)/2)+(($K$2*I$12^3)/3)-($L$2/(2*I$12^2))+$N$2 -> 232.51857 | J14: =($H$2*LN(J$12))+($I$2*J$12)+(($J$2*J$12^2)/2)+(($K$2*J$12^3)/3)-($L$2/(2*J$12^2))+$N$2 -> 240.2045 | K14: =($H$2*LN(K$12))+($I$2*K$12)+(($J$2*K$12^2)/2)+(($K$2*K$12^3)/3)-($L$2/(2*K$12^2))+$N$2 -> 247.5478 | L14: =($H$2*LN(L$12))+($I$2*L$12)+(($J$2*L$12^2)/2)+(($K$2*L$12^3)/3)-($L$2/(2*L$12^2))+$N$2 -> 252.70431 | M14: =($H$2*LN(M$12))+($I$2*M$12)+(($J$2*M$12^2)/2)+(($K$2*M$12^3)/3)-($L$2/(2*M$12^2))+$N$2 -> 254.5695 | N14: =($H$2*LN(N$12))+($I$2*N$12)+(($J$2*N$12^2)/2)+(($K$2*N$12^3)/3)-($L$2/(2*N$12^2))+$N$2 -> 261.28671 | O14: =($H$2*LN(O$12))+($I$2*O$12)+(($J$2*O$12^2)/2)+(($K$2*O$12^3)/3)-($L$2/(2*O$12^2))+$N$2 -> 266.00664 | P14: =($H$2*LN(P$12))+($I$2*P$12)+(($J$2*P$12^2)/2)+(($K$2*P$12^3)/3)-($L$2/(2*P$12^2))+$N$2 -> 267.71437
A15: dH_crack | B15: 84440 | G15: Cp (K) | H15: =$H$2+($I$2*H$12)+($J$2*H$12^2)+($K$2*H$12^3)+($L$2/(H$12^2)) -> 57.791275 | I15: =$H$2+($I$2*I$12)+($J$2*I$12^2)+($K$2*I$12^3)+($L$2/(I$12^2)) -> 62.927011 | J15: =$H$2+($I$2*J$12)+($J$2*J$12^2)+($K$2*J$12^3)+($L$2/(J$12^2)) -> 67.595776 | K15: =$H$2+($I$2*K$12)+($J$2*K$12^2)+($K$2*K$12^3)+($L$2/(K$12^2)) -> 71.794054 | L15: =$H$2+($I$2*L$12)+($J$2*L$12^2)+($K$2*L$12^3)+($L$2/(L$12^2)) -> 74.56892 | M15: =$H$2+($I$2*M$12)+($J$2*M$12^2)+($K$2*M$12^3)+($L$2/(M$12^2)) -> 75.53507 | N15: =$H$2+($I$2*N$12)+($J$2*N$12^2)+($K$2*N$12^3)+($L$2/(N$12^2)) -> 78.840794 | O15: =$H$2+($I$2*O$12)+($J$2*O$12^2)+($K$2*O$12^3)+($L$2/(O$12^2)) -> 80.994408 | P15: =$H$2+($I$2*P$12)+($J$2*P$12^2)+($K$2*P$12^3)+($L$2/(P$12^2)) -> 81.738071
A16: K_Boud | B16: 1930000000
